Workbook
Name Avg_MilesPerKWh: Constants!$C$6
Name ChargeCost_GasPricePerGallon_Range: 'Charge Stats'!$V$4:$V$6000
Name ChargeStats_AllGasCost_Range: 'Charge Stats'!$AC$4:$AC$6000
Name ChargeStats_AllHomeChg_Range: 'Charge Stats'!$AD$4:$AD$6000
Name ChargeStats_AllSuperChgCost_Range: 'Charge Stats'!$AB$4:$AB$6000
Name ChargeStats_AvgPricePerGallonoOfGas: 'Charge Stats'!$V$2
Name ChargeStats_ChargeCostHome_Range: 'Charge Stats'!$T$4:$T$6000
Name ChargeStats_ChargeCostSuperCharger_Range: 'Charge Stats'!$S$4:$S$6000
Name ChargeStats_ChargeGasCostDifference_Range: 'Charge Stats'!$Y$4:$Y$6000
Name ChargeStats_ChgEndTime_Range: 'Charge Stats'!$M$4:$M$6000
Name ChargeStats_ChgHours_Range: 'Charge Stats'!$N$4:$N$6000
Name ChargeStats_ChgPct_Range: 'Charge Stats'!$K$4:$K$6000
Name ChargeStats_ChgPctAfter_Range: 'Charge Stats'!$J$4:$J$6000
Name ChargeStats_ChgPctStart_Range: 'Charge Stats'!$I$4:$I$6000
Name ChargeStats_ChgStartTime_Range: 'Charge Stats'!$L$4:$L$6000
Name ChargeStats_CostPerKWhHome_Range: 'Charge Stats'!$R$4:$R$6000
Name ChargeStats_CostPerKWhSuperCharger_Range: 'Charge Stats'!$Q$4:$Q$6000
Name ChargeStats_Date_Range: 'Charge Stats'!$A$4:$A$6000
Name ChargeStats_EstGallonsOfGas_Range: 'Charge Stats'!$W$4:$W$6000
Name ChargeStats_EstGasCost_Range: 'Charge Stats'!$X$4:$X$6000
Name ChargeStats_GasCostPctSaving_Range: 'Charge Stats'!$Z$4:$Z$6000
Name ChargeStats_GasPricePerGallon_Range: 'Charge Stats'!$V$4:$V$6000
Name ChargeStats_HomeChgSaving_Range: 'Charge Stats'!$AA$4:$AA$6000
Name ChargeStats_HomeKWh_Range: 'Charge Stats'!$G$4:$G$6000
Name ChargeStats_HomeL1KWh_Range: 'Charge Stats'!$E$4:$E$6000
Name ChargeStats_HomeL2KWh_Range: 'Charge Stats'!$F$4:$F$6000
Name ChargeStats_MaxMilesAfterChg_Range: 'Charge Stats'!$O$4:$O$6000
Name ChargeStats_MilesPerKWh_Range: 'Charge Stats'!$P$4:$P$6000
Name ChargeStats_OdometerMiles_Range: 'Charge Stats'!$B$4:$B$6000
Name ChargeStats_SuperChargerKWh_Range: 'Charge Stats'!$D$4:$D$6000
Name ChargeStats_TotalChargeCost_Range: 'Charge Stats'!$U$4:$U$6000
Name ChargeStats_TotalKWh_Range: 'Charge Stats'!$H$4:$H$6000
Name Cost_PerKWh_Home_ChargeStats: 'Charge Stats'!$R$2
Name FPLBillHistory_BilledPricePerKW_Range: 'FPL Bill History'!$M$1:$M$200
Name FPLBillHistory_BillFromDate_Range: 'FPL Bill History'!$C$1:$C$200
Name FPLBillHistory_BillToDate_Range: 'FPL Bill History'!$D$1:$D$200
Name KWh_Cost_Home: 'Charge Stats'!$R$2
Name MaxChargePercent: Constants!$C$2
Name MPG_Kia: Constants!$C$1
Name Total_GallonsGas: 'Charge Stats'!$W$2
Name Total_KWs: 'Charge Stats'!$H$2

Sheet Charge Stats
B2: =MAX(B5:B6000) -> 1775 | C2: =SUM(C5:C6000) -> 1775 | D2: =SUM(D5:D6000) -> 143 | E2: =SUM(E5:E6000) -> 107 | F2: =SUM(F5:F6000) -> 271 | G2: =SUM(G5:G6000) -> 378 | H2: =D2+G2 -> 521 | K2: =SUM(K5:K6000) -> 669 | N2: =SUM(N5:N6000) -> 159.2 | P2: =C2/H2 -> 3.4069098 | Q2: =AVERAGEIF(Q5:Q6000,">0") -> 0.38758621 | R2: =AVERAGEIF(R5:R6000,">0") -> 0.13703226 | S2: =D2*Q2 -> 55.424828 | T2: =G2*R2 -> 51.798195 | U2: =SUM(S2:T2) -> 107.22302 | V2: =AVERAGEIF(V5:V6000,">0") -> 2.7437931 | W2: =C2/MPG_Kia -> 71 | X2: =V2*W2 -> 194.80931 | Y2: =X2-U2 -> 87.586288 | Z2: =(X2-U2)/X2 -> 0.44960011 | AA2: =SUM(AA5:AA6000) -> 96.655428 | AB2: =SUM(AB5:AB6000) -> 196.63 | AC2: =SUM(AC5:AC6000) -> 195.1592 | AD2: =SUM(AD5:AD6000) -> 71.392572 | AE2: =SUM(AE5:AE6000) -> -1.4708 | AF2: =SUM(AF5:AF6000) -> 123.76663 | AG2: =SUM(AG5:AG6000) -> 125.23743 | AH2: =SUM(AH5:AH6000) -> 1391.6 | ... AX2: =SUM(AX5:AX6000) -> 0
A3: Tesla App | B3: Driving Stats | D3: Charging Stats | S3: Charging Cost Totals | V3: Gas Cost | Y3: Gas Saving | AB3: Super Vs Home Charge Cost | AH3: Gas Emission Saved (Lbs) | AP3: Natural Gas Emission from Electric Power Plant (Lbs)
A4: Date | B4: Odometer Miles | C4: Miles Driven | D4: Super Charger KWh | E4: Home L1 Chg KWh | F4: Home L2 Chg KWh | G4: Home KWh | H4: Total KWh | I4: chg % start | J4: Chg % after | K4: Chg % | L4: Chg Start Time | M4: Chg End Time | N4: Chg hours | O4: max miles after chg | P4: Miles per KWh | Q4: Cost / KWh Super Charger | R4: Cost Per KWh Home | S4: Charge Cost Super Chg | T4: Charge Cost Home | U4: Total Charge Cost | V4: Gas Price Per Gal | W4: Est Gallons of gas | X4: Est Gas Cost | Y4: Charge / Gas Cost Difference | Z4: % saving | AA4: Home Chg Saving | AB4: all Super Chg Cost | AC4: all Gas Cost | AD4: All Home Chg cost | AE4: Amt Gas aved All Super Chg | AF4: Amt Gas Saved All Home Chg | AG4: Amt Saved Home vs Super Chg | AH4: Carbon dioxide (CO₂) | AI4: Water vapor (H₂O) | AJ4: **Nitrogen** N₂ | AK4: Carbon monoxide (CO) | AL4: Nitrogen oxides (NOₓ) | AM4: Unburned hydrocarbons (VOCs) | AN4: Particulate matter (PM2.5) | AO4: Sulfur dioxide (SO₂) | AP4: cu Ft Natural Gas | AQ4: Carbon dioxide (CO₂) | AR4: Water vapor (H₂O) | AS4: **Nitrogen** N₂ | AT4: Carbon monoxide (CO) | AU4: Nitrogen oxides (NOₓ) | AV4: Unburned hydrocarbons (VOCs) | AW4: Particulate matter (PM2.5) | AX4: Sulfur dioxide (SO₂)
A5: 45900 | B5: 0 | C5: {=IF(B5=0, 0, B5 - INDEX(B$4:B4, MAX(IF(B$4:B4<>0, ROW(B$4:B4)-ROW(B$4)+1))))} -> 0 | D5: 0 | E5: 0 | F5: 0 | G5: =E5+F5 -> 0 | H5: =D5+G5 -> 0 | I5: 0 | J5: 0 | K5: =J5-I5 -> 0 | N5: 0 | O5: 0 | P5: =IF(H5>0,C5/H5,0) -> 0 | Q5: 0 | R5: {=INDEX(FPLBillHistory_BilledPricePerKW_Range, MATCH(1, (A5>=FPLBillHistory_BillFromDate_Range)*(A5<=FPLBillHistory_BillToDate_Range), 0))} -> 0.13709935 | S5: =D5*Q5 -> 0 | T5: =G5*R5 -> 0 | U5: =SUM(S5:T5) -> 0 | V5: 0 | Y5: =X5-U5 -> 0 | Z5: =IFERROR((X5-U5)/X5,0) -> 0 | AA5: =G5*Q5-G5*R5 -> 0 | AB5: =H5*Q5 -> 0 | AC5: =V5*W5 -> 0 | AD5: =H5*R5 -> 0 | AE5: =X5-AB5 -> 0 | AF5: =X5-AD5 -> 0 | AG5: =AB5-AD5 -> 0
A6: 45901 | B6: 0 | C6: {=IF(B6=0, 0, B6 - INDEX(B$4:B5, MAX(IF(B$4:B5<>0, ROW(B$4:B5)-ROW(B$4)+1))))} -> 0 | D6: 0 | E6: 0 | F6: 0 | G6: =E6+F6 -> 0 | H6: =D6+G6 -> 0 | I6: 0 | J6: 0 | K6: =J6-I6 -> 0 | N6: 0 | O6: 0 | P6: =IF(H6>0,C6/H6,0) -> 0 | Q6: 0 | R6: {=INDEX(FPLBillHistory_BilledPricePerKW_Range, MATCH(1, (A6>=FPLBillHistory_BillFromDate_Range)*(A6<=FPLBillHistory_BillToDate_Range), 0))} -> 0.13709935 | S6: =D6*Q6 -> 0 | T6: =G6*R6 -> 0 | U6: =SUM(S6:T6) -> 0 | V6: 0 | W6: =C6/MPG_Kia -> 0 | X6: =V6*W6 -> 0 | Y6: =X6-U6 -> 0 | Z6: =IFERROR((X6-U6)/X6,0) -> 0 | AA6: =G6*Q6-G6*R6 -> 0 | AB6: =H6*Q6 -> 0 | AC6: =V6*W6 -> 0 | AD6: =H6*R6 -> 0 | AE6: =X6-AB6 -> 0 | AF6: =X6-AD6 -> 0 | AG6: =AB6-AD6 -> 0 | AH6: ='Gas Chemistry'!$B$11*$W6 -> 0 | AI6: ='Gas Chemistry'!$B$12*$W6 -> 0 | AJ6: 0 | AK6: ='Gas Chemistry'!$B$13*$W6 -> 0 | AL6: ='Gas Chemistry'!$B$14*$W6 -> 0 | AM6: ='Gas Chemistry'!$B$15*$W6 -> 0 | AN6: ='Gas Chemistry'!$B$16*$W6 -> 0 | AO6: ='Gas Chemistry'!$B$17*$W6 -> 0 | AP6: =H6*Constants!$C$14 -> 0 | AQ6: ='Gas Chemistry'!$C$122*$AP6 -> 0 | AR6: ='Gas Chemistry'!$C$123*$AP6 -> 0 | AS6: ='Gas Chemistry'!$C$127*$AP6 -> 0 | AT6: ='Gas Chemistry'!$C$124*$AP6 -> 0 | AU6: ='Gas Chemistry'!$C$126*$AP6 -> 0 | AV6: ='Gas Chemistry'!$C$125*$AP6 -> 0 | AW6: 0 | AX6: 0
A7: 45902 | B7: 0 | C7: {=IF(B7=0, 0, B7 - INDEX(B$4:B6, MAX(IF(B$4:B6<>0, ROW(B$4:B6)-ROW(B$4)+1))))} -> 0 | D7: 0 | E7: 0 | F7: 0 | G7: =E7+F7 -> 0 | H7: =D7+G7 -> 0 | I7: 0 | J7: 0 | K7: =J7-I7 -> 0 | N7: 0 | O7: 0 | P7: =IF(H7>0,C7/H7,0) -> 0 | Q7: 0 | R7: {=INDEX(FPLBillHistory_BilledPricePerKW_Range, MATCH(1, (A7>=FPLBillHistory_BillFromDate_Range)*(A7<=FPLBillHistory_BillToDate_Range), 0))} -> 0.13709935 | S7: =D7*Q7 -> 0 | T7: =G7*R7 -> 0 | U7: =SUM(S7:T7) -> 0 | V7: 0 | W7: =C7/MPG_Kia -> 0 | X7: =V7*W7 -> 0 | Y7: =X7-U7 -> 0 | Z7: =IFERROR((X7-U7)/X7,0) -> 0 | AA7: =G7*Q7-G7*R7 -> 0 | AB7: =H7*Q7 -> 0 | AC7: =V7*W7 -> 0 | AD7: =H7*R7 -> 0 | AE7: =X7-AB7 -> 0 | AF7: =X7-AD7 -> 0 | AG7: =AB7-AD7 -> 0 | AH7: ='Gas Chemistry'!$B$11*$W7 -> 0 | AI7: ='Gas Chemistry'!$B$12*$W7 -> 0 | AJ7: 0 | AK7: ='Gas Chemistry'!$B$13*$W7 -> 0 | AL7: ='Gas Chemistry'!$B$14*$W7 -> 0 | AM7: ='Gas Chemistry'!$B$15*$W7 -> 0 | AN7: ='Gas Chemistry'!$B$16*$W7 -> 0 | AO7: ='Gas Chemistry'!$B$17*$W7 -> 0 | AP7: =H7*Constants!$C$14 -> 0 | AQ7: ='Gas Chemistry'!$C$122*$AP7 -> 0 | AR7: ='Gas Chemistry'!$C$123*$AP7 -> 0 | AS7: ='Gas Chemistry'!$C$127*$AP7 -> 0 | AT7: ='Gas Chemistry'!$C$124*$AP7 -> 0 | AU7: ='Gas Chemistry'!$C$126*$AP7 -> 0 | AV7: ='Gas Chemistry'!$C$125*$AP7 -> 0 | AW7: 0 | AX7: 0
A8: 45903 | B8: 0 | C8: {=IF(B8=0, 0, B8 - INDEX(B$4:B7, MAX(IF(B$4:B7<>0, ROW(B$4:B7)-ROW(B$4)+1))))} -> 0 | D8: 0 | E8: 0 | F8: 0 | G8: =E8+F8 -> 0 | H8: =D8+G8 -> 0 | I8: 0 | J8: 0 | K8: =J8-I8 -> 0 | N8: 0 | O8: 0 | P8: =IF(H8>0,C8/H8,0) -> 0 | Q8: 0 | R8: {=INDEX(FPLBillHistory_BilledPricePerKW_Range, MATCH(1, (A8>=FPLBillHistory_BillFromDate_Range)*(A8<=FPLBillHistory_BillToDate_Range), 0))} -> 0.13709935 | S8: =D8*Q8 -> 0 | T8: =G8*R8 -> 0 | U8: =SUM(S8:T8) -> 0 | V8: 0 | W8: =C8/MPG_Kia -> 0 | X8: =V8*W8 -> 0 | Y8: =X8-U8 -> 0 | Z8: =IFERROR((X8-U8)/X8,0) -> 0 | AA8: =G8*Q8-G8*R8 -> 0 | AB8: =H8*Q8 -> 0 | AC8: =V8*W8 -> 0 | AD8: =H8*R8 -> 0 | AE8: =X8-AB8 -> 0 | AF8: =X8-AD8 -> 0 | AG8: =AB8-AD8 -> 0 | AH8: ='Gas Chemistry'!$B$11*$W8 -> 0 | AI8: ='Gas Chemistry'!$B$12*$W8 -> 0 | AJ8: 0 | AK8: ='Gas Chemistry'!$B$13*$W8 -> 0 | AL8: ='Gas Chemistry'!$B$14*$W8 -> 0 | AM8: ='Gas Chemistry'!$B$15*$W8 -> 0 | AN8: ='Gas Chemistry'!$B$16*$W8 -> 0 | AO8: ='Gas Chemistry'!$B$17*$W8 -> 0 | AP8: =H8*Constants!$C$14 -> 0 | AQ8: ='Gas Chemistry'!$C$122*$AP8 -> 0 | AR8: ='Gas Chemistry'!$C$123*$AP8 -> 0 | AS8: ='Gas Chemistry'!$C$127*$AP8 -> 0 | AT8: ='Gas Chemistry'!$C$124*$AP8 -> 0 | AU8: ='Gas Chemistry'!$C$126*$AP8 -> 0 | AV8: ='Gas Chemistry'!$C$125*$AP8 -> 0 | AW8: 0 | AX8: 0
A9: 45904 | B9: 0 | C9: {=IF(B9=0, 0, B9 - INDEX(B$4:B8, MAX(IF(B$4:B8<>0, ROW(B$4:B8)-ROW(B$4)+1))))} -> 0 | D9: 0 | E9: 0 | F9: 0 | G9: =E9+F9 -> 0 | H9: =D9+G9 -> 0 | I9: 0 | J9: 0 | K9: =J9-I9 -> 0 | N9: 0 | O9: 0 | P9: =IF(H9>0,C9/H9,0) -> 0 | Q9: 0 | R9: {=INDEX(FPLBillHistory_BilledPricePerKW_Range, MATCH(1, (A9>=FPLBillHistory_BillFromDate_Range)*(A9<=FPLBillHistory_BillToDate_Range), 0))} -> 0.13709935 | S9: =D9*Q9 -> 0 | T9: =G9*R9 -> 0 | U9: =SUM(S9:T9) -> 0 | V9: 0 | W9: =C9/MPG_Kia -> 0 | X9: =V9*W9 -> 0 | Y9: =X9-U9 -> 0 | Z9: =IFERROR((X9-U9)/X9,0) -> 0 | AA9: =G9*Q9-G9*R9 -> 0 | AB9: =H9*Q9 -> 0 | AC9: =V9*W9 -> 0 | AD9: =H9*R9 -> 0 | AE9: =X9-AB9 -> 0 | AF9: =X9-AD9 -> 0 | AG9: =AB9-AD9 -> 0 | AH9: ='Gas Chemistry'!$B$11*$W9 -> 0 | AI9: ='Gas Chemistry'!$B$12*$W9 -> 0 | AJ9: 0 | AK9: ='Gas Chemistry'!$B$13*$W9 -> 0 | AL9: ='Gas Chemistry'!$B$14*$W9 -> 0 | AM9: ='Gas Chemistry'!$B$15*$W9 -> 0 | AN9: ='Gas Chemistry'!$B$16*$W9 -> 0 | AO9: ='Gas Chemistry'!$B$17*$W9 -> 0 | AP9: =H9*Constants!$C$14 -> 0 | AQ9: ='Gas Chemistry'!$C$122*$AP9 -> 0 | AR9: ='Gas Chemistry'!$C$123*$AP9 -> 0 | AS9: ='Gas Chemistry'!$C$127*$AP9 -> 0 | AT9: ='Gas Chemistry'!$C$124*$AP9 -> 0 | AU9: ='Gas Chemistry'!$C$126*$AP9 -> 0 | AV9: ='Gas Chemistry'!$C$125*$AP9 -> 0 | AW9: 0 | AX9: 0
A10: 45905 | B10: 130 | C10: 130 | D10: 49 | E10: 0 | F10: 0 | G10: =E10+F10 -> 0 | H10: =D10+G10 -> 49 | I10: 0 | J10: 80 | K10: =J10-I10 -> 80 | L10: 0.83333333 | M10: 0 | N10: 0.3 | O10: 0 | P10: =IF(H10>0,C10/H10,0) -> 2.6530612 | Q10: 0.34 | R10: {=INDEX(FPLBillHistory_BilledPricePerKW_Range, MATCH(1, (A10>=FPLBillHistory_BillFromDate_Range)*(A10<=FPLBillHistory_BillToDate_Range), 0))} -> 0.13709935 | S10: =D10*Q10 -> 16.66 | T10: =G10*R10 -> 0 | U10: =SUM(S10:T10) -> 16.66 | V10: 2.75 | W10: =C10/MPG_Kia -> 5.2 | X10: =V10*W10 -> 14.3 | Y10: =X10-U10 -> -2.36 | Z10: =IFERROR((X10-U10)/X10,0) -> -0.16503497 | AA10: =G10*Q10-G10*R10 -> 0 | AB10: =H10*Q10 -> 16.66 | AC10: =V10*W10 -> 14.3 | AD10: =H10*R10 -> 6.717868 | AE10: =X10-AB10 -> -2.36 | AF10: =X10-AD10 -> 7.582132 | AG10: =AB10-AD10 -> 9.942132 | AH10: ='Gas Chemistry'!$B$11*$W10 -> 101.92 | AI10: ='Gas Chemistry'!$B$12*$W10 -> 41.6 | AJ10: 0 | AK10: ='Gas Chemistry'!$B$13*$W10 -> 0.104 | AL10: ='Gas Chemistry'!$B$14*$W10 -> 0.052 | AM10: ='Gas Chemistry'!$B$15*$W10 -> 0.0104 | AN10: ='Gas Chemistry'!$B$16*$W10 -> 0.0052 | AO10: ='Gas Chemistry'!$B$17*$W10 -> 0.0208 | AP10: =H10*Constants!$C$14 -> 167.188 | AQ10: ='Gas Chemistry'!$C$122*$AP10 -> 19.560996 | AR10: ='Gas Chemistry'!$C$123*$AP10 -> 24.075072 | AS10: ='Gas Chemistry'!$C$127*$AP10 -> 785.7836 | AT10: ='Gas Chemistry'!$C$124*$AP10 -> 0.014043792 | AU10: ='Gas Chemistry'!$C$126*$AP10 -> 0.0167188 | AV10: ='Gas Chemistry'!$C$125*$AP10 -> 0.00083594 | AW10: 0 | AX10: 0
A11: 45906 | B11: 0 | C11: {=IF(B11=0, 0, B11 - INDEX(B$4:B10, MAX(IF(B$4:B10<>0, ROW(B$4:B10)-ROW(B$4)+1))))} -> 0 | D11: 0 | E11: 0 | F11: 0 | G11: =E11+F11 -> 0 | H11: =D11+G11 -> 0 | I11: 0 | J11: 0 | K11: =J11-I11 -> 0 | N11: 0 | O11: 0 | P11: =IF(H11>0,C11/H11,0) -> 0 | Q11: 0 | R11: {=INDEX(FPLBillHistory_BilledPricePerKW_Range, MATCH(1, (A11>=FPLBillHistory_BillFromDate_Range)*(A11<=FPLBillHistory_BillToDate_Range), 0))} -> 0.13709935 | S11: =D11*Q11 -> 0 | T11: =G11*R11 -> 0 | U11: =SUM(S11:T11) -> 0 | V11: 0 | W11: =C11/MPG_Kia -> 0 | X11: =V11*W11 -> 0 | Y11: =X11-U11 -> 0 | Z11: =IFERROR((X11-U11)/X11,0) -> 0 | AA11: =G11*Q11-G11*R11 -> 0 | AB11: =H11*Q11 -> 0 | AC11: =V11*W11 -> 0 | AD11: =H11*R11 -> 0 | AE11: =X11-AB11 -> 0 | AF11: =X11-AD11 -> 0 | AG11: =AB11-AD11 -> 0 | AH11: ='Gas Chemistry'!$B$11*$W11 -> 0 | AI11: ='Gas Chemistry'!$B$12*$W11 -> 0 | AJ11: 0 | AK11: ='Gas Chemistry'!$B$13*$W11 -> 0 | AL11: ='Gas Chemistry'!$B$14*$W11 -> 0 | AM11: ='Gas Chemistry'!$B$15*$W11 -> 0 | AN11: ='Gas Chemistry'!$B$16*$W11 -> 0 | AO11: ='Gas Chemistry'!$B$17*$W11 -> 0 | AP11: =H11*Constants!$C$14 -> 0 | AQ11: ='Gas Chemistry'!$C$122*$AP11 -> 0 | AR11: ='Gas Chemistry'!$C$123*$AP11 -> 0 | AS11: ='Gas Chemistry'!$C$127*$AP11 -> 0 | AT11: ='Gas Chemistry'!$C$124*$AP11 -> 0 | AU11: ='Gas Chemistry'!$C$126*$AP11 -> 0 | AV11: ='Gas Chemistry'!$C$125*$AP11 -> 0 | AW11: 0 | AX11: 0
A12: 45907 | B12: 0 | C12: {=IF(B12=0, 0, B12 - INDEX(B$4:B11, MAX(IF(B$4:B11<>0, ROW(B$4:B11)-ROW(B$4)+1))))} -> 0 | D12: 0 | E12: 0 | F12: 0 | G12: =E12+F12 -> 0 | H12: =D12+G12 -> 0 | I12: 0 | J12: 0 | K12: =J12-I12 -> 0 | N12: 0 | O12: 0 | P12: =IF(H12>0,C12/H12,0) -> 0 | Q12: 0 | R12: {=INDEX(FPLBillHistory_BilledPricePerKW_Range, MATCH(1, (A12>=FPLBillHistory_BillFromDate_Range)*(A12<=FPLBillHistory_BillToDate_Range), 0))} -> 0.13709935 | S12: =D12*Q12 -> 0 | T12: =G12*R12 -> 0 | U12: =SUM(S12:T12) -> 0 | V12: 0 | W12: =C12/MPG_Kia -> 0 | X12: =V12*W12 -> 0 | Y12: =X12-U12 -> 0 | Z12: =IFERROR((X12-U12)/X12,0) -> 0 | AA12: =G12*Q12-G12*R12 -> 0 | AB12: =H12*Q12 -> 0 | AC12: =V12*W12 -> 0 | AD12: =H12*R12 -> 0 | AE12: =X12-AB12 -> 0 | AF12: =X12-AD12 -> 0 | AG12: =AB12-AD12 -> 0 | AH12: ='Gas Chemistry'!$B$11*$W12 -> 0 | AI12: ='Gas Chemistry'!$B$12*$W12 -> 0 | AJ12: 0 | AK12: ='Gas Chemistry'!$B$13*$W12 -> 0 | AL12: ='Gas Chemistry'!$B$14*$W12 -> 0 | AM12: ='Gas Chemistry'!$B$15*$W12 -> 0 | AN12: ='Gas Chemistry'!$B$16*$W12 -> 0 | AO12: ='Gas Chemistry'!$B$17*$W12 -> 0 | AP12: =H12*Constants!$C$14 -> 0 | AQ12: ='Gas Chemistry'!$C$122*$AP12 -> 0 | AR12: ='Gas Chemistry'!$C$123*$AP12 -> 0 | AS12: ='Gas Chemistry'!$C$127*$AP12 -> 0 | AT12: ='Gas Chemistry'!$C$124*$AP12 -> 0 | AU12: ='Gas Chemistry'!$C$126*$AP12 -> 0 | AV12: ='Gas Chemistry'!$C$125*$AP12 -> 0 | AW12: 0 | AX12: 0
A13: 45908 | B13: 300 | C13: {=IF(B13=0, 0, B13 - INDEX(B$4:B12, MAX(IF(B$4:B12<>0, ROW(B$4:B12)-ROW(B$4)+1))))} -> 170 | D13: 38 | E13: 0 | F13: 0 | G13: =E13+F13 -> 0 | H13: =D13+G13 -> 38 | I13: 0 | J13: 80 | K13: =J13-I13 -> 80 | L13: 0.83333333 | M13: 0 | N13: 0.3 | O13: 0 | P13: =IF(H13>0,C13/H13,0) -> 4.4736842 | Q13: 0.34 | R13: {=INDEX(FPLBillHistory_BilledPricePerKW_Range, MATCH(1, (A13>=FPLBillHistory_BillFromDate_Range)*(A13<=FPLBillHistory_BillToDate_Range), 0))} -> 0.13702268 | S13: =D13*Q13 -> 12.92 | T13: =G13*R13 -> 0 | U13: =SUM(S13:T13) -> 12.92 | V13: 2.75 | W13: =C13/MPG_Kia -> 6.8 | X13: =V13*W13 -> 18.7 | Y13: =X13-U13 -> 5.78 | Z13: =IFERROR((X13-U13)/X13,0) -> 0.30909091 | AA13: =G13*Q13-G13*R13 -> 0 | AB13: =H13*Q13 -> 12.92 | AC13: =V13*W13 -> 18.7 | AD13: =H13*R13 -> 5.2068617 | AE13: =X13-AB13 -> 5.78 | AF13: =X13-AD13 -> 13.493138 | AG13: =AB13-AD13 -> 7.7131383 | AH13: ='Gas Chemistry'!$B$11*$W13 -> 133.28 | AI13: ='Gas Chemistry'!$B$12*$W13 -> 54.4 | AJ13: 0 | AK13: ='Gas Chemistry'!$B$13*$W13 -> 0.136 | AL13: ='Gas Chemistry'!$B$14*$W13 -> 0.068 | AM13: ='Gas Chemistry'!$B$15*$W13 -> 0.0136 | AN13: ='Gas Chemistry'!$B$16*$W13 -> 0.0068 | AO13: ='Gas Chemistry'!$B$17*$W13 -> 0.0272 | AP13: =H13*Constants!$C$14 -> 129.656 | AQ13: ='Gas Chemistry'!$C$122*$AP13 -> 15.169752 | AR13: ='Gas Chemistry'!$C$123*$AP13 -> 18.670464 | AS13: ='Gas Chemistry'!$C$127*$AP13 -> 609.3832 | AT13: ='Gas Chemistry'!$C$124*$AP13 -> 0.010891104 | AU13: ='Gas Chemistry'!$C$126*$AP13 -> 0.0129656 | AV13: ='Gas Chemistry'!$C$125*$AP13 -> 0.00064828 | AW13: 0 | AX13: 0
A14: 45909 | B14: 0 | C14: {=IF(B14=0, 0, B14 - INDEX(B$4:B13, MAX(IF(B$4:B13<>0, ROW(B$4:B13)-ROW(B$4)+1))))} -> 0 | D14: 0 | E14: 0 | F14: 0 | G14: =E14+F14 -> 0 | H14: =D14+G14 -> 0 | I14: 0 | J14: 0 | K14: =J14-I14 -> 0 | N14: 0 | O14: 0 | P14: =IF(H14>0,C14/H14,0) -> 0 | Q14: 0 | R14: {=INDEX(FPLBillHistory_BilledPricePerKW_Range, MATCH(1, (A14>=FPLBillHistory_BillFromDate_Range)*(A14<=FPLBillHistory_BillToDate_Range), 0))} -> 0.13702268 | S14: =D14*Q14 -> 0 | T14: =G14*R14 -> 0 | U14: =SUM(S14:T14) -> 0 | V14: 0 | W14: =C14/MPG_Kia -> 0 | X14: =V14*W14 -> 0 | Y14: =X14-U14 -> 0 | Z14: =IFERROR((X14-U14)/X14,0) -> 0 | AA14: =G14*Q14-G14*R14 -> 0 | AB14: =H14*Q14 -> 0 | AC14: =V14*W14 -> 0 | AD14: =H14*R14 -> 0 | AE14: =X14-AB14 -> 0 | AF14: =X14-AD14 -> 0 | AG14: =AB14-AD14 -> 0 | AH14: ='Gas Chemistry'!$B$11*$W14 -> 0 | AI14: ='Gas Chemistry'!$B$12*$W14 -> 0 | AJ14: 0 | AK14: ='Gas Chemistry'!$B$13*$W14 -> 0 | AL14: ='Gas Chemistry'!$B$14*$W14 -> 0 | AM14: ='Gas Chemistry'!$B$15*$W14 -> 0 | AN14: ='Gas Chemistry'!$B$16*$W14 -> 0 | AO14: ='Gas Chemistry'!$B$17*$W14 -> 0 | AP14: =H14*Constants!$C$14 -> 0 | AQ14: ='Gas Chemistry'!$C$122*$AP14 -> 0 | AR14: ='Gas Chemistry'!$C$123*$AP14 -> 0 | AS14: ='Gas Chemistry'!$C$127*$AP14 -> 0 | AT14: ='Gas Chemistry'!$C$124*$AP14 -> 0 | AU14: ='Gas Chemistry'!$C$126*$AP14 -> 0 | AV14: ='Gas Chemistry'!$C$125*$AP14 -> 0 | AW14: 0 | AX14: 0
A15: 45910 | B15: 0 | C15: {=IF(B15=0, 0, B15 - INDEX(B$4:B14, MAX(IF(B$4:B14<>0, ROW(B$4:B14)-ROW(B$4)+1))))} -> 0 | D15: 0 | E15: 0 | F15: 0 | G15: =E15+F15 -> 0 | H15: =D15+G15 -> 0 | I15: 0 | J15: 0 | K15: =J15-I15 -> 0 | N15: 0 | O15: 0 | P15: =IF(H15>0,C15/H15,0) -> 0 | Q15: 0 | R15: {=INDEX(FPLBillHistory_BilledPricePerKW_Range, MATCH(1, (A15>=FPLBillHistory_BillFromDate_Range)*(A15<=FPLBillHistory_BillToDate_Range), 0))} -> 0.13702268 | S15: =D15*Q15 -> 0 | T15: =G15*R15 -> 0 | U15: =SUM(S15:T15) -> 0 | V15: 0 | W15: =C15/MPG_Kia -> 0 | X15: =V15*W15 -> 0 | Y15: =X15-U15 -> 0 | Z15: =IFERROR((X15-U15)/X15,0) -> 0 | AA15: =G15*Q15-G15*R15 -> 0 | AB15: =H15*Q15 -> 0 | AC15: =V15*W15 -> 0 | AD15: =H15*R15 -> 0 | AE15: =X15-AB15 -> 0 | AF15: =X15-AD15 -> 0 | AG15: =AB15-AD15 -> 0 | AH15: ='Gas Chemistry'!$B$11*$W15 -> 0 | AI15: ='Gas Chemistry'!$B$12*$W15 -> 0 | AJ15: 0 | AK15: ='Gas Chemistry'!$B$13*$W15 -> 0 | AL15: ='Gas Chemistry'!$B$14*$W15 -> 0 | AM15: ='Gas Chemistry'!$B$15*$W15 -> 0 | AN15: ='Gas Chemistry'!$B$16*$W15 -> 0 | AO15: ='Gas Chemistry'!$B$17*$W15 -> 0 | AP15: =H15*Constants!$C$14 -> 0 | AQ15: ='Gas Chemistry'!$C$122*$AP15 -> 0 | AR15: ='Gas Chemistry'!$C$123*$AP15 -> 0 | AS15: ='Gas Chemistry'!$C$127*$AP15 -> 0 | AT15: ='Gas Chemistry'!$C$124*$AP15 -> 0 | AU15: ='Gas Chemistry'!$C$126*$AP15 -> 0 | AV15: ='Gas Chemistry'!$C$125*$AP15 -> 0 | AW15: 0 | AX15: 0
A16: 45911 | B16: 0 | C16: {=IF(B16=0, 0, B16 - INDEX(B$4:B15, MAX(IF(B$4:B15<>0, ROW(B$4:B15)-ROW(B$4)+1))))} -> 0 | D16: 0 | E16: 0 | F16: 0 | G16: =E16+F16 -> 0 | H16: =D16+G16 -> 0 | I16: 0 | J16: 0 | K16: =J16-I16 -> 0 | N16: 0 | O16: 0 | P16: =IF(H16>0,C16/H16,0) -> 0 | Q16: 0 | R16: {=INDEX(FPLBillHistory_BilledPricePerKW_Range, MATCH(1, (A16>=FPLBillHistory_BillFromDate_Range)*(A16<=FPLBillHistory_BillToDate_Range), 0))} -> 0.13702268 | S16: =D16*Q16 -> 0 | T16: =G16*R16 -> 0 | U16: =SUM(S16:T16) -> 0 | V16: 0 | W16: =C16/MPG_Kia -> 0 | X16: =V16*W16 -> 0 | Y16: =X16-U16 -> 0 | Z16: =IFERROR((X16-U16)/X16,0) -> 0 | AA16: =G16*Q16-G16*R16 -> 0 | AB16: =H16*Q16 -> 0 | AC16: =V16*W16 -> 0 | AD16: =H16*R16 -> 0 | AE16: =X16-AB16 -> 0 | AF16: =X16-AD16 -> 0 | AG16: =AB16-AD16 -> 0 | AH16: ='Gas Chemistry'!$B$11*$W16 -> 0 | AI16: ='Gas Chemistry'!$B$12*$W16 -> 0 | AJ16: 0 | AK16: ='Gas Chemistry'!$B$13*$W16 -> 0 | AL16: ='Gas Chemistry'!$B$14*$W16 -> 0 | AM16: ='Gas Chemistry'!$B$15*$W16 -> 0 | AN16: ='Gas Chemistry'!$B$16*$W16 -> 0 | AO16: ='Gas Chemistry'!$B$17*$W16 -> 0 | AP16: =H16*Constants!$C$14 -> 0 | AQ16: ='Gas Chemistry'!$C$122*$AP16 -> 0 | AR16: ='Gas Chemistry'!$C$123*$AP16 -> 0 | AS16: ='Gas Chemistry'!$C$127*$AP16 -> 0 | AT16: ='Gas Chemistry'!$C$124*$AP16 -> 0 | AU16: ='Gas Chemistry'!$C$126*$AP16 -> 0 | AV16: ='Gas Chemistry'!$C$125*$AP16 -> 0 | AW16: 0 | AX16: 0
A17: 45912 | B17: 325 | C17: {=IF(B17=0, 0, B17 - INDEX(B$4:B16, MAX(IF(B$4:B16<>0, ROW(B$4:B16)-ROW(B$4)+1))))} -> 25 | D17: 0 | E17: 4 | F17: 0 | G17: =E17+F17 -> 4 | H17: =D17+G17 -> 4 | I17: 0 | J17: 0 | K17: =J17-I17 -> 0 | L17: 0.83333333 | M17: 0 | N17: 8 | O17: 0 | P17: =IF(H17>0,C17/H17,0) -> 6.25 | Q17: 0.39 | R17: {=INDEX(FPLBillHistory_BilledPricePerKW_Range, MATCH(1, (A17>=FPLBillHistory_BillFromDate_Range)*(A17<=FPLBillHistory_BillToDate_Range), 0))} -> 0.13702268 | S17: =D17*Q17 -> 0 | T17: =G17*R17 -> 0.54809071 | U17: =SUM(S17:T17) -> 0.54809071 | V17: 2.75 | W17: =C17/MPG_Kia -> 1 | X17: =V17*W17 -> 2.75 | Y17: =X17-U17 -> 2.2019093 | Z17: =IFERROR((X17-U17)/X17,0) -> 0.80069429 | AA17: =G17*Q17-G17*R17 -> 1.0119093 | AB17: =H17*Q17 -> 1.56 | AC17: =V17*W17 -> 2.75 | AD17: =H17*R17 -> 0.54809071 | AE17: =X17-AB17 -> 1.19 | AF17: =X17-AD17 -> 2.2019093 | AG17: =AB17-AD17 -> 1.0119093 | AH17: ='Gas Chemistry'!$B$11*$W17 -> 19.6 | AI17: ='Gas Chemistry'!$B$12*$W17 -> 8 | AJ17: 0 | AK17: ='Gas Chemistry'!$B$13*$W17 -> 0.02 | AL17: ='Gas Chemistry'!$B$14*$W17 -> 0.01 | AM17: ='Gas Chemistry'!$B$15*$W17 -> 0.002 | AN17: ='Gas Chemistry'!$B$16*$W17 -> 0.001 | AO17: ='Gas Chemistry'!$B$17*$W17 -> 0.004 | AP17: =H17*Constants!$C$14 -> 13.648 | AQ17: ='Gas Chemistry'!$C$122*$AP17 -> 1.596816 | AR17: ='Gas Chemistry'!$C$123*$AP17 -> 1.965312 | AS17: ='Gas Chemistry'!$C$127*$AP17 -> 64.1456 | AT17: ='Gas Chemistry'!$C$124*$AP17 -> 0.001146432 | AU17: ='Gas Chemistry'!$C$126*$AP17 -> 0.0013648 | AV17: ='Gas Chemistry'!$C$125*$AP17 -> 6.824e-05 | AW17: 0 | AX17: 0
A18: 45913 | B18: 425 | C18: {=IF(B18=0, 0, B18 - INDEX(B$4:B17, MAX(IF(B$4:B17<>0, ROW(B$4:B17)-ROW(B$4)+1))))} -> 100 | D18: 38 | E18: 10 | F18: 0 | G18: =E18+F18 -> 10 | H18: =D18+G18 -> 48 | I18: 0 | J18: 80 | K18: =J18-I18 -> 80 | L18: 0.83333333 | M18: 0.33333333 | N18: 12 | O18: 0 | P18: =IF(H18>0,C18/H18,0) -> 2.0833333 | Q18: 0.3 | R18: {=INDEX(FPLBillHistory_BilledPricePerKW_Range, MATCH(1, (A18>=FPLBillHistory_BillFromDate_Range)*(A18<=FPLBillHistory_BillToDate_Range), 0))} -> 0.13702268 | S18: =D18*Q18 -> 11.4 | T18: =G18*R18 -> 1.3702268 | U18: =SUM(S18:T18) -> 12.770227 | V18: 2.75 | W18: =C18/MPG_Kia -> 4 | X18: =V18*W18 -> 11 | Y18: =X18-U18 -> -1.7702268 | Z18: =IFERROR((X18-U18)/X18,0) -> -0.16092971 | AA18: =G18*Q18-G18*R18 -> 1.6297732 | AB18: =H18*Q18 -> 14.4 | AC18: =V18*W18 -> 11 | AD18: =H18*R18 -> 6.5770885 | AE18: =X18-AB18 -> -3.4 | AF18: =X18-AD18 -> 4.4229115 | AG18: =AB18-AD18 -> 7.8229115 | AH18: ='Gas Chemistry'!$B$11*$W18 -> 78.4 | AI18: ='Gas Chemistry'!$B$12*$W18 -> 32 | AJ18: 0 | AK18: ='Gas Chemistry'!$B$13*$W18 -> 0.08 | AL18: ='Gas Chemistry'!$B$14*$W18 -> 0.04 | AM18: ='Gas Chemistry'!$B$15*$W18 -> 0.008 | AN18: ='Gas Chemistry'!$B$16*$W18 -> 0.004 | AO18: ='Gas Chemistry'!$B$17*$W18 -> 0.016 | AP18: =H18*Constants!$C$14 -> 163.776 | AQ18: ='Gas Chemistry'!$C$122*$AP18 -> 19.161792 | AR18: ='Gas Chemistry'!$C$123*$AP18 -> 23.583744 | AS18: ='Gas Chemistry'!$C$127*$AP18 -> 769.7472 | AT18: ='Gas Chemistry'!$C$124*$AP18 -> 0.013757184 | AU18: ='Gas Chemistry'!$C$126*$AP18 -> 0.0163776 | AV18: ='Gas Chemistry'!$C$125*$AP18 -> 0.00081888 | AW18: 0 | AX18: 0
A19: 45914 | B19: 430 | C19: {=IF(B19=0, 0, B19 - INDEX(B$4:B18, MAX(IF(B$4:B18<>0, ROW(B$4:B18)-ROW(B$4)+1))))} -> 5 | D19: 0 | E19: 7 | F19: 0 | G19: =E19+F19 -> 7 | H19: =D19+G19 -> 7 | I19: 0 | J19: 0 | K19: =J19-I19 -> 0 | L19: 0.83333333 | M19: 0.20833333 | N19: 9 | O19: 0 | P19: =IF(H19>0,C19/H19,0) -> 0.71428571 | Q19: 0.39 | R19: {=INDEX(FPLBillHistory_BilledPricePerKW_Range, MATCH(1, (A19>=FPLBillHistory_BillFromDate_Range)*(A19<=FPLBillHistory_BillToDate_Range), 0))} -> 0.13702268 | S19: =D19*Q19 -> 0 | T19: =G19*R19 -> 0.95915874 | U19: =SUM(S19:T19) -> 0.95915874 | V19: 2.75 | W19: =C19/MPG_Kia -> 0.2 | X19: =V19*W19 -> 0.55 | Y19: =X19-U19 -> -0.40915874 | Z19: =IFERROR((X19-U19)/X19,0) -> -0.74392499 | AA19: =G19*Q19-G19*R19 -> 1.7708413 | AB19: =H19*Q19 -> 2.73 | AC19: =V19*W19 -> 0.55 | AD19: =H19*R19 -> 0.95915874 | AE19: =X19-AB19 -> -2.18 | AF19: =X19-AD19 -> -0.40915874 | AG19: =AB19-AD19 -> 1.7708413 | AH19: ='Gas Chemistry'!$B$11*$W19 -> 3.92 | AI19: ='Gas Chemistry'!$B$12*$W19 -> 1.6 | AJ19: 0 | AK19: ='Gas Chemistry'!$B$13*$W19 -> 0.004 | AL19: ='Gas Chemistry'!$B$14*$W19 -> 0.002 | AM19: ='Gas Chemistry'!$B$15*$W19 -> 0.0004 | AN19: ='Gas Chemistry'!$B$16*$W19 -> 0.0002 | AO19: ='Gas Chemistry'!$B$17*$W19 -> 0.0008 | AP19: =H19*Constants!$C$14 -> 23.884 | AQ19: ='Gas Chemistry'!$C$122*$AP19 -> 2.794428 | AR19: ='Gas Chemistry'!$C$123*$AP19 -> 3.439296 | AS19: ='Gas Chemistry'!$C$127*$AP19 -> 112.2548 | AT19: ='Gas Chemistry'!$C$124*$AP19 -> 0.002006256 | AU19: ='Gas Chemistry'!$C$126*$AP19 -> 0.0023884 | AV19: ='Gas Chemistry'!$C$125*$AP19 -> 0.00011942 | AW19: 0 | AX19: 0
A20: 45915 | B20: 0 | C20: {=IF(B20=0, 0, B20 - INDEX(B$4:B19, MAX(IF(B$4:B19<>0, ROW(B$4:B19)-ROW(B$4)+1))))} -> 0 | D20: 0 | E20: 0 | F20: 0 | G20: =E20+F20 -> 0 | H20: =D20+G20 -> 0 | I20: 0 | J20: 0 | K20: =J20-I20 -> 0 | N20: 0 | O20: 0 | P20: =IF(H20>0,C20/H20,0) -> 0 | Q20: 0 | R20: {=INDEX(FPLBillHistory_BilledPricePerKW_Range, MATCH(1, (A20>=FPLBillHistory_BillFromDate_Range)*(A20<=FPLBillHistory_BillToDate_Range), 0))} -> 0.13702268 | S20: =D20*Q20 -> 0 | T20: =G20*R20 -> 0 | U20: =SUM(S20:T20) -> 0 | V20: 0 | W20: =C20/MPG_Kia -> 0 | X20: =V20*W20 -> 0 | Y20: =X20-U20 -> 0 | Z20: =IFERROR((X20-U20)/X20,0) -> 0 | AA20: =G20*Q20-G20*R20 -> 0 | AB20: =H20*Q20 -> 0 | AC20: =V20*W20 -> 0 | AD20: =H20*R20 -> 0 | AE20: =X20-AB20 -> 0 | AF20: =X20-AD20 -> 0 | AG20: =AB20-AD20 -> 0 | AH20: ='Gas Chemistry'!$B$11*$W20 -> 0 | AI20: ='Gas Chemistry'!$B$12*$W20 -> 0 | AJ20: 0 | AK20: ='Gas Chemistry'!$B$13*$W20 -> 0 | AL20: ='Gas Chemistry'!$B$14*$W20 -> 0 | AM20: ='Gas Chemistry'!$B$15*$W20 -> 0 | AN20: ='Gas Chemistry'!$B$16*$W20 -> 0 | AO20: ='Gas Chemistry'!$B$17*$W20 -> 0 | AP20: =H20*Constants!$C$14 -> 0 | AQ20: ='Gas Chemistry'!$C$122*$AP20 -> 0 | AR20: ='Gas Chemistry'!$C$123*$AP20 -> 0 | AS20: ='Gas Chemistry'!$C$127*$AP20 -> 0 | AT20: ='Gas Chemistry'!$C$124*$AP20 -> 0 | AU20: ='Gas Chemistry'!$C$126*$AP20 -> 0 | AV20: ='Gas Chemistry'!$C$125*$AP20 -> 0 | AW20: 0 | AX20: 0
A21: 45916 | B21: 552 | C21: {=IF(B21=0, 0, B21 - INDEX(B$4:B20, MAX(IF(B$4:B20<>0, ROW(B$4:B20)-ROW(B$4)+1))))} -> 122 | D21: 0 | E21: 21 | F21: 0 | G21: =E21+F21 -> 21 | H21: =D21+G21 -> 21 | I21: 60 | J21: 73 | K21: =J21-I21 -> 13 | L21: 0.83333333 | M21: 0.20833333 | N21: 18 | O21: 0 | P21: =IF(H21>0,C21/H21,0) -> 5.8095238 | Q21: 0.39 | R21: {=INDEX(FPLBillHistory_BilledPricePerKW_Range, MATCH(1, (A21>=FPLBillHistory_BillFromDate_Range)*(A21<=FPLBillHistory_BillToDate_Range), 0))} -> 0.13702268 | S21: =D21*Q21 -> 0 | T21: =G21*R21 -> 2.8774762 | U21: =SUM(S21:T21) -> 2.8774762 | V21: 2.75 | W21: =C21/MPG_Kia -> 4.88 | X21: =V21*W21 -> 13.42 | Y21: =X21-U21 -> 10.542524 | Z21: =IFERROR((X21-U21)/X21,0) -> 0.78558299 | AA21: =G21*Q21-G21*R21 -> 5.3125238 | AB21: =H21*Q21 -> 8.19 | AC21: =V21*W21 -> 13.42 | AD21: =H21*R21 -> 2.8774762 | AE21: =X21-AB21 -> 5.23 | AF21: =X21-AD21 -> 10.542524 | AG21: =AB21-AD21 -> 5.3125238 | AH21: ='Gas Chemistry'!$B$11*$W21 -> 95.648 | AI21: ='Gas Chemistry'!$B$12*$W21 -> 39.04 | AJ21: 0 | AK21: ='Gas Chemistry'!$B$13*$W21 -> 0.0976 | AL21: ='Gas Chemistry'!$B$14*$W21 -> 0.0488 | AM21: ='Gas Chemistry'!$B$15*$W21 -> 0.00976 | AN21: ='Gas Chemistry'!$B$16*$W21 -> 0.00488 | AO21: ='Gas Chemistry'!$B$17*$W21 -> 0.01952 | AP21: =H21*Constants!$C$14 -> 71.652 | AQ21: ='Gas Chemistry'!$C$122*$AP21 -> 8.383284 | AR21: ='Gas Chemistry'!$C$123*$AP21 -> 10.317888 | AS21: ='Gas Chemistry'!$C$127*$AP21 -> 336.7644 | AT21: ='Gas Chemistry'!$C$124*$AP21 -> 0.006018768 | AU21: ='Gas Chemistry'!$C$126*$AP21 -> 0.0071652 | AV21: ='Gas Chemistry'!$C$125*$AP21 -> 0.00035826 | AW21: 0 | AX21: 0
A22: 45917 | B22: 561 | C22: {=IF(B22=0, 0, B22 - INDEX(B$4:B21, MAX(IF(B$4:B21<>0, ROW(B$4:B21)-ROW(B$4)+1))))} -> 9 | D22: 0 | E22: 8 | F22: 0 | G22: =E22+F22 -> 8 | H22: =D22+G22 -> 8 | I22: 70 | J22: 80 | K22: =J22-I22 -> 10 | L22: 0.83333333 | M22: 0.20833333 | N22: 9 | O22: 282 | P22: =IF(H22>0,C22/H22,0) -> 1.125 | Q22: 0.39 | R22: {=INDEX(FPLBillHistory_BilledPricePerKW_Range, MATCH(1, (A22>=FPLBillHistory_BillFromDate_Range)*(A22<=FPLBillHistory_BillToDate_Range), 0))} -> 0.13702268 | S22: =D22*Q22 -> 0 | T22: =G22*R22 -> 1.0961814 | U22: =SUM(S22:T22) -> 1.0961814 | V22: 2.75 | W22: =C22/MPG_Kia -> 0.36 | X22: =V22*W22 -> 0.99 | Y22: =X22-U22 -> -0.10618142 | Z22: =IFERROR((X22-U22)/X22,0) -> -0.10725396 | AA22: =G22*Q22-G22*R22 -> 2.0238186 | AB22: =H22*Q22 -> 3.12 | AC22: =V22*W22 -> 0.99 | AD22: =H22*R22 -> 1.0961814 | AE22: =X22-AB22 -> -2.13 | AF22: =X22-AD22 -> -0.10618142 | AG22: =AB22-AD22 -> 2.0238186 | AH22: ='Gas Chemistry'!$B$11*$W22 -> 7.056 | AI22: ='Gas Chemistry'!$B$12*$W22 -> 2.88 | AJ22: 0 | AK22: ='Gas Chemistry'!$B$13*$W22 -> 0.0072 | AL22: ='Gas Chemistry'!$B$14*$W22 -> 0.0036 | AM22: ='Gas Chemistry'!$B$15*$W22 -> 0.00072 | AN22: ='Gas Chemistry'!$B$16*$W22 -> 0.00036 | AO22: ='Gas Chemistry'!$B$17*$W22 -> 0.00144 | AP22: =H22*Constants!$C$14 -> 27.296 | AQ22: ='Gas Chemistry'!$C$122*$AP22 -> 3.193632 | AR22: ='Gas Chemistry'!$C$123*$AP22 -> 3.930624 | AS22: ='Gas Chemistry'!$C$127*$AP22 -> 128.2912 | AT22: ='Gas Chemistry'!$C$124*$AP22 -> 0.002292864 | AU22: ='Gas Chemistry'!$C$126*$AP22 -> 0.0027296 | AV22: ='Gas Chemistry'!$C$125*$AP22 -> 0.00013648 | AW22: 0 | AX22: 0
A23: 45918 | B23: 569 | C23: {=IF(B23=0, 0, B23 - INDEX(B$4:B22, MAX(IF(B$4:B22<>0, ROW(B$4:B22)-ROW(B$4)+1))))} -> 8 | D23: 0 | E23: 7 | F23: 0 | G23: =E23+F23 -> 7 | H23: =D23+G23 -> 7 | I23: 73 | J23: 80 | K23: =J23-I23 -> 7 | L23: 0.83333333 | M23: 0.20833333 | N23: 9 | O23: 282 | P23: =IF(H23>0,C23/H23,0) -> 1.1428571 | Q23: 0.39 | R23: {=INDEX(FPLBillHistory_BilledPricePerKW_Range, MATCH(1, (A23>=FPLBillHistory_BillFromDate_Range)*(A23<=FPLBillHistory_BillToDate_Range), 0))} -> 0.13702268 | S23: =D23*Q23 -> 0 | T23: =G23*R23 -> 0.95915874 | U23: =SUM(S23:T23) -> 0.95915874 | V23: 2.75 | W23: =C23/MPG_Kia -> 0.32 | X23: =V23*W23 -> 0.88 | Y23: =X23-U23 -> -0.079158742 | Z23: =IFERROR((X23-U23)/X23,0) -> -0.089953116 | AA23: =G23*Q23-G23*R23 -> 1.7708413 | AB23: =H23*Q23 -> 2.73 | AC23: =V23*W23 -> 0.88 | AD23: =H23*R23 -> 0.95915874 | AE23: =X23-AB23 -> -1.85 | AF23: =X23-AD23 -> -0.079158742 | AG23: =AB23-AD23 -> 1.7708413 | AH23: ='Gas Chemistry'!$B$11*$W23 -> 6.272 | AI23: ='Gas Chemistry'!$B$12*$W23 -> 2.56 | AJ23: 0 | AK23: ='Gas Chemistry'!$B$13*$W23 -> 0.0064 | AL23: ='Gas Chemistry'!$B$14*$W23 -> 0.0032 | AM23: ='Gas Chemistry'!$B$15*$W23 -> 0.00064 | AN23: ='Gas Chemistry'!$B$16*$W23 -> 0.00032 | AO23: ='Gas Chemistry'!$B$17*$W23 -> 0.00128 | AP23: =H23*Constants!$C$14 -> 23.884 | AQ23: ='Gas Chemistry'!$C$122*$AP23 -> 2.794428 | AR23: ='Gas Chemistry'!$C$123*$AP23 -> 3.439296 | AS23: ='Gas Chemistry'!$C$127*$AP23 -> 112.2548 | AT23: ='Gas Chemistry'!$C$124*$AP23 -> 0.002006256 | AU23: ='Gas Chemistry'!$C$126*$AP23 -> 0.0023884 | AV23: ='Gas Chemistry'!$C$125*$AP23 -> 0.00011942 | AW23: 0 | AX23: 0
A24: 45919 | B24: 594 | C24: {=IF(B24=0, 0, B24 - INDEX(B$4:B23, MAX(IF(B$4:B23<>0, ROW(B$4:B23)-ROW(B$4)+1))))} -> 25 | D24: 0 | E24: 7 | F24: 0 | G24: =E24+F24 -> 7 | H24: =D24+G24 -> 7 | I24: 71 | J24: 80 | K24: =J24-I24 -> 9 | L24: 0.83333333 | M24: 0.20833333 | N24: 9 | O24: 282 | P24: =IF(H24>0,C24/H24,0) -> 3.5714286 | Q24: 0.39 | R24: {=INDEX(FPLBillHistory_BilledPricePerKW_Range, MATCH(1, (A24>=FPLBillHistory_BillFromDate_Range)*(A24<=FPLBillHistory_BillToDate_Range), 0))} -> 0.13702268 | S24: =D24*Q24 -> 0 | T24: =G24*R24 -> 0.95915874 | U24: =SUM(S24:T24) -> 0.95915874 | V24: 2.75 | W24: =C24/MPG_Kia -> 1 | X24: =V24*W24 -> 2.75 | Y24: =X24-U24 -> 1.7908413 | Z24: =IFERROR((X24-U24)/X24,0) -> 0.651215 | AA24: =G24*Q24-G24*R24 -> 1.7708413 | AB24: =H24*Q24 -> 2.73 | AC24: =V24*W24 -> 2.75 | AD24: =H24*R24 -> 0.95915874 | AE24: =X24-AB24 -> 0.02 | AF24: =X24-AD24 -> 1.7908413 | AG24: =AB24-AD24 -> 1.7708413 | AH24: ='Gas Chemistry'!$B$11*$W24 -> 19.6 | AI24: ='Gas Chemistry'!$B$12*$W24 -> 8 | AJ24: 0 | AK24: ='Gas Chemistry'!$B$13*$W24 -> 0.02 | AL24: ='Gas Chemistry'!$B$14*$W24 -> 0.01 | AM24: ='Gas Chemistry'!$B$15*$W24 -> 0.002 | AN24: ='Gas Chemistry'!$B$16*$W24 -> 0.001 | AO24: ='Gas Chemistry'!$B$17*$W24 -> 0.004 | AP24: =H24*Constants!$C$14 -> 23.884 | AQ24: ='Gas Chemistry'!$C$122*$AP24 -> 2.794428 | AR24: ='Gas Chemistry'!$C$123*$AP24 -> 3.439296 | AS24: ='Gas Chemistry'!$C$127*$AP24 -> 112.2548 | AT24: ='Gas Chemistry'!$C$124*$AP24 -> 0.002006256 | AU24: ='Gas Chemistry'!$C$126*$AP24 -> 0.0023884 | AV24: ='Gas Chemistry'!$C$125*$AP24 -> 0.00011942 | AW24: 0 | AX24: 0
A25: 45920 | B25: 676 | C25: {=IF(B25=0, 0, B25 - INDEX(B$4:B24, MAX(IF(B$4:B24<>0, ROW(B$4:B24)-ROW(B$4)+1))))} -> 82 | D25: 0 | E25: 13 | F25: 0 | G25: =E25+F25 -> 13 | H25: =D25+G25 -> 13 | I25: 51 | J25: 70 | K25: =J25-I25 -> 19 | L25: 0.83333333 | M25: 0.375 | N25: 13 | O25: 248 | P25: =IF(H25>0,C25/H25,0) -> 6.3076923 | Q25: 0.39 | R25: {=INDEX(FPLBillHistory_BilledPricePerKW_Range, MATCH(1, (A25>=FPLBillHistory_BillFromDate_Range)*(A25<=FPLBillHistory_BillToDate_Range), 0))} -> 0.13702268 | S25: =D25*Q25 -> 0 | T25: =G25*R25 -> 1.7812948 | U25: =SUM(S25:T25) -> 1.7812948 | V25: 2.75 | W25: =C25/MPG_Kia -> 3.28 | X25: =V25*W25 -> 9.02 | Y25: =X25-U25 -> 7.2387052 | Z25: =IFERROR((X25-U25)/X25,0) -> 0.80251721 | AA25: =G25*Q25-G25*R25 -> 3.2887052 | AB25: =H25*Q25 -> 5.07 | AC25: =V25*W25 -> 9.02 | AD25: =H25*R25 -> 1.7812948 | AE25: =X25-AB25 -> 3.95 | AF25: =X25-AD25 -> 7.2387052 | AG25: =AB25-AD25 -> 3.2887052 | AH25: ='Gas Chemistry'!$B$11*$W25 -> 64.288 | AI25: ='Gas Chemistry'!$B$12*$W25 -> 26.24 | AJ25: 0 | AK25: ='Gas Chemistry'!$B$13*$W25 -> 0.0656 | AL25: ='Gas Chemistry'!$B$14*$W25 -> 0.0328 | AM25: ='Gas Chemistry'!$B$15*$W25 -> 0.00656 | AN25: ='Gas Chemistry'!$B$16*$W25 -> 0.00328 | AO25: ='Gas Chemistry'!$B$17*$W25 -> 0.01312 | AP25: =H25*Constants!$C$14 -> 44.356 | AQ25: ='Gas Chemistry'!$C$122*$AP25 -> 5.189652 | AR25: ='Gas Chemistry'!$C$123*$AP25 -> 6.387264 | AS25: ='Gas Chemistry'!$C$127*$AP25 -> 208.4732 | AT25: ='Gas Chemistry'!$C$124*$AP25 -> 0.003725904 | AU25: ='Gas Chemistry'!$C$126*$AP25 -> 0.0044356 | AV25: ='Gas Chemistry'!$C$125*$AP25 -> 0.00022178 | AW25: 0 | AX25: 0
A26: 45921 | B26: 682 | C26: {=IF(B26=0, 0, B26 - INDEX(B$4:B25, MAX(IF(B$4:B25<>0, ROW(B$4:B25)-ROW(B$4)+1))))} -> 6 | D26: 0 | E26: 15 | F26: 0 | G26: =E26+F26 -> 15 | H26: =D26+G26 -> 15 | I26: 62 | J26: 78 | K26: =J26-I26 -> 16 | L26: 0.875 | M26: 0.375 | N26: 12 | O26: 276 | P26: =IF(H26>0,C26/H26,0) -> 0.4 | Q26: 0.39 | R26: {=INDEX(FPLBillHistory_BilledPricePerKW_Range, MATCH(1, (A26>=FPLBillHistory_BillFromDate_Range)*(A26<=FPLBillHistory_BillToDate_Range), 0))} -> 0.13702268 | S26: =D26*Q26 -> 0 | T26: =G26*R26 -> 2.0553402 | U26: =SUM(S26:T26) -> 2.0553402 | V26: 2.75 | W26: =C26/MPG_Kia -> 0.24 | X26: =V26*W26 -> 0.66 | Y26: =X26-U26 -> -1.3953402 | Z26: =IFERROR((X26-U26)/X26,0) -> -2.1141518 | AA26: =G26*Q26-G26*R26 -> 3.7946598 | AB26: =H26*Q26 -> 5.85 | AC26: =V26*W26 -> 0.66 | AD26: =H26*R26 -> 2.0553402 | AE26: =X26-AB26 -> -5.19 | AF26: =X26-AD26 -> -1.3953402 | AG26: =AB26-AD26 -> 3.7946598 | AH26: ='Gas Chemistry'!$B$11*$W26 -> 4.704 | AI26: ='Gas Chemistry'!$B$12*$W26 -> 1.92 | AJ26: 0 | AK26: ='Gas Chemistry'!$B$13*$W26 -> 0.0048 | AL26: ='Gas Chemistry'!$B$14*$W26 -> 0.0024 | AM26: ='Gas Chemistry'!$B$15*$W26 -> 0.00048 | AN26: ='Gas Chemistry'!$B$16*$W26 -> 0.00024 | AO26: ='Gas Chemistry'!$B$17*$W26 -> 0.00096 | AP26: =H26*Constants!$C$14 -> 51.18 | AQ26: ='Gas Chemistry'!$C$122*$AP26 -> 5.98806 | AR26: ='Gas Chemistry'!$C$123*$AP26 -> 7.36992 | AS26: ='Gas Chemistry'!$C$127*$AP26 -> 240.546 | AT26: ='Gas Chemistry'!$C$124*$AP26 -> 0.00429912 | AU26: ='Gas Chemistry'!$C$126*$AP26 -> 0.005118 | AV26: ='Gas Chemistry'!$C$125*$AP26 -> 0.0002559 | AW26: 0 | AX26: 0
A27: 45922 | B27: 693 | C27: {=IF(B27=0, 0, B27 - INDEX(B$4:B26, MAX(IF(B$4:B26<>0, ROW(B$4:B26)-ROW(B$4)+1))))} -> 11 | D27: 0 | E27: 15 | F27: 0 | G27: =E27+F27 -> 15 | H27: =D27+G27 -> 15 | I27: 66 | J27: 80 | K27: =J27-I27 -> 14 | L27: 0.83333333 | M27: 0.22638889 | N27: 9 | O27: 282 | P27: =IF(H27>0,C27/H27,0) -> 0.73333333 | Q27: 0.39 | R27: {=INDEX(FPLBillHistory_BilledPricePerKW_Range, MATCH(1, (A27>=FPLBillHistory_BillFromDate_Range)*(A27<=FPLBillHistory_BillToDate_Range), 0))} -> 0.13702268 | S27: =D27*Q27 -> 0 | T27: =G27*R27 -> 2.0553402 | U27: =SUM(S27:T27) -> 2.0553402 | V27: 2.79 | W27: =C27/MPG_Kia -> 0.44 | X27: =V27*W27 -> 1.2276 | Y27: =X27-U27 -> -0.82774016 | Z27: =IFERROR((X27-U27)/X27,0) -> -0.67427514 | AA27: =G27*Q27-G27*R27 -> 3.7946598 | AB27: =H27*Q27 -> 5.85 | AC27: =V27*W27 -> 1.2276 | AD27: =H27*R27 -> 2.0553402 | AE27: =X27-AB27 -> -4.6224 | AF27: =X27-AD27 -> -0.82774016 | AG27: =AB27-AD27 -> 3.7946598 | AH27: ='Gas Chemistry'!$B$11*$W27 -> 8.624 | AI27: ='Gas Chemistry'!$B$12*$W27 -> 3.52 | AJ27: 0 | AK27: ='Gas Chemistry'!$B$13*$W27 -> 0.0088 | AL27: ='Gas Chemistry'!$B$14*$W27 -> 0.0044 | AM27: ='Gas Chemistry'!$B$15*$W27 -> 0.00088 | AN27: ='Gas Chemistry'!$B$16*$W27 -> 0.00044 | AO27: ='Gas Chemistry'!$B$17*$W27 -> 0.00176 | AP27: =H27*Constants!$C$14 -> 51.18 | AQ27: ='Gas Chemistry'!$C$122*$AP27 -> 5.98806 | AR27: ='Gas Chemistry'!$C$123*$AP27 -> 7.36992 | AS27: ='Gas Chemistry'!$C$127*$AP27 -> 240.546 | AT27: ='Gas Chemistry'!$C$124*$AP27 -> 0.00429912 | AU27: ='Gas Chemistry'!$C$126*$AP27 -> 0.005118 | AV27: ='Gas Chemistry'!$C$125*$AP27 -> 0.0002559 | AW27: 0 | AX27: 0
A28: 45923 | B28: 0 | C28: {=IF(B28=0, 0, B28 - INDEX(B$4:B27, MAX(IF(B$4:B27<>0, ROW(B$4:B27)-ROW(B$4)+1))))} -> 0 | D28: 0 | E28: 0 | F28: 0 | G28: =E28+F28 -> 0 | H28: =D28+G28 -> 0 | I28: 0 | J28: 0 | K28: =J28-I28 -> 0 | N28: 0 | O28: 0 | P28: =IF(H28>0,C28/H28,0) -> 0 | Q28: 0 | R28: {=INDEX(FPLBillHistory_BilledPricePerKW_Range, MATCH(1, (A28>=FPLBillHistory_BillFromDate_Range)*(A28<=FPLBillHistory_BillToDate_Range), 0))} -> 0.13702268 | S28: =D28*Q28 -> 0 | T28: =G28*R28 -> 0 | U28: =SUM(S28:T28) -> 0 | V28: 0 | W28: =C28/MPG_Kia -> 0 | X28: =V28*W28 -> 0 | Y28: =X28-U28 -> 0 | Z28: =IFERROR((X28-U28)/X28,0) -> 0 | AA28: =G28*Q28-G28*R28 -> 0 | AB28: =H28*Q28 -> 0 | AC28: =V28*W28 -> 0 | AD28: =H28*R28 -> 0 | AE28: =X28-AB28 -> 0 | AF28: =X28-AD28 -> 0 | AG28: =AB28-AD28 -> 0 | AH28: ='Gas Chemistry'!$B$11*$W28 -> 0 | AI28: ='Gas Chemistry'!$B$12*$W28 -> 0 | AJ28: 0 | AK28: ='Gas Chemistry'!$B$13*$W28 -> 0 | AL28: ='Gas Chemistry'!$B$14*$W28 -> 0 | AM28: ='Gas Chemistry'!$B$15*$W28 -> 0 | AN28: ='Gas Chemistry'!$B$16*$W28 -> 0 | AO28: ='Gas Chemistry'!$B$17*$W28 -> 0 | AP28: =H28*Constants!$C$14 -> 0 | AQ28: ='Gas Chemistry'!$C$122*$AP28 -> 0 | AR28: ='Gas Chemistry'!$C$123*$AP28 -> 0 | AS28: ='Gas Chemistry'!$C$127*$AP28 -> 0 | AT28: ='Gas Chemistry'!$C$124*$AP28 -> 0 | AU28: ='Gas Chemistry'!$C$126*$AP28 -> 0 | AV28: ='Gas Chemistry'!$C$125*$AP28 -> 0 | AW28: 0 | AX28: 0
A29: 45924 | B29: 756 | C29: {=IF(B29=0, 0, B29 - INDEX(B$4:B28, MAX(IF(B$4:B28<>0, ROW(B$4:B28)-ROW(B$4)+1))))} -> 63 | D29: 0 | E29: 0 | F29: 9 | G29: =E29+F29 -> 9 | H29: =D29+G29 -> 9 | I29: 68 | J29: 80 | K29: =J29-I29 -> 12 | L29: 0.041666667 | M29: 0.11458333 | N29: 1.75 | O29: 282 | P29: =IF(H29>0,C29/H29,0) -> 7 | Q29: 0.39 | R29: {=INDEX(FPLBillHistory_BilledPricePerKW_Range, MATCH(1, (A29>=FPLBillHistory_BillFromDate_Range)*(A29<=FPLBillHistory_BillToDate_Range), 0))} -> 0.13702268 | S29: =D29*Q29 -> 0 | T29: =G29*R29 -> 1.2332041 | U29: =SUM(S29:T29) -> 1.2332041 | V29: 2.79 | W29: =C29/MPG_Kia -> 2.52 | X29: =V29*W29 -> 7.0308 | Y29: =X29-U29 -> 5.7975959 | Z29: =IFERROR((X29-U29)/X29,0) -> 0.82459975 | AA29: =G29*Q29-G29*R29 -> 2.2767959 | AB29: =H29*Q29 -> 3.51 | AC29: =V29*W29 -> 7.0308 | AD29: =H29*R29 -> 1.2332041 | AE29: =X29-AB29 -> 3.5208 | AF29: =X29-AD29 -> 5.7975959 | AG29: =AB29-AD29 -> 2.2767959 | AH29: ='Gas Chemistry'!$B$11*$W29 -> 49.392 | AI29: ='Gas Chemistry'!$B$12*$W29 -> 20.16 | AJ29: 0 | AK29: ='Gas Chemistry'!$B$13*$W29 -> 0.0504 | AL29: ='Gas Chemistry'!$B$14*$W29 -> 0.0252 | AM29: ='Gas Chemistry'!$B$15*$W29 -> 0.00504 | AN29: ='Gas Chemistry'!$B$16*$W29 -> 0.00252 | AO29: ='Gas Chemistry'!$B$17*$W29 -> 0.01008 | AP29: =H29*Constants!$C$14 -> 30.708 | AQ29: ='Gas Chemistry'!$C$122*$AP29 -> 3.592836 | AR29: ='Gas Chemistry'!$C$123*$AP29 -> 4.421952 | AS29: ='Gas Chemistry'!$C$127*$AP29 -> 144.3276 | AT29: ='Gas Chemistry'!$C$124*$AP29 -> 0.002579472 | AU29: ='Gas Chemistry'!$C$126*$AP29 -> 0.0030708 | AV29: ='Gas Chemistry'!$C$125*$AP29 -> 0.00015354 | AW29: 0 | AX29: 0
A30: 45925 | B30: 0 | C30: {=IF(B30=0, 0, B30 - INDEX(B$4:B29, MAX(IF(B$4:B29<>0, ROW(B$4:B29)-ROW(B$4)+1))))} -> 0 | D30: 0 | E30: 0 | F30: 0 | G30: =E30+F30 -> 0 | H30: =D30+G30 -> 0 | I30: 0 | J30: 0 | K30: =J30-I30 -> 0 | N30: 0 | O30: 0 | P30: =IF(H30>0,C30/H30,0) -> 0 | Q30: 0 | R30: {=INDEX(FPLBillHistory_BilledPricePerKW_Range, MATCH(1, (A30>=FPLBillHistory_BillFromDate_Range)*(A30<=FPLBillHistory_BillToDate_Range), 0))} -> 0.13702268 | S30: =D30*Q30 -> 0 | T30: =G30*R30 -> 0 | U30: =SUM(S30:T30) -> 0 | V30: 0 | W30: =C30/MPG_Kia -> 0 | X30: =V30*W30 -> 0 | Y30: =X30-U30 -> 0 | Z30: =IFERROR((X30-U30)/X30,0) -> 0 | AA30: =G30*Q30-G30*R30 -> 0 | AB30: =H30*Q30 -> 0 | AC30: =V30*W30 -> 0 | AD30: =H30*R30 -> 0 | AE30: =X30-AB30 -> 0 | AF30: =X30-AD30 -> 0 | AG30: =AB30-AD30 -> 0 | AH30: ='Gas Chemistry'!$B$11*$W30 -> 0 | AI30: ='Gas Chemistry'!$B$12*$W30 -> 0 | AJ30: 0 | AK30: ='Gas Chemistry'!$B$13*$W30 -> 0 | AL30: ='Gas Chemistry'!$B$14*$W30 -> 0 | AM30: ='Gas Chemistry'!$B$15*$W30 -> 0 | AN30: ='Gas Chemistry'!$B$16*$W30 -> 0 | AO30: ='Gas Chemistry'!$B$17*$W30 -> 0 | AP30: =H30*Constants!$C$14 -> 0 | AQ30: ='Gas Chemistry'!$C$122*$AP30 -> 0 | AR30: ='Gas Chemistry'!$C$123*$AP30 -> 0 | AS30: ='Gas Chemistry'!$C$127*$AP30 -> 0 | AT30: ='Gas Chemistry'!$C$124*$AP30 -> 0 | AU30: ='Gas Chemistry'!$C$126*$AP30 -> 0 | AV30: ='Gas Chemistry'!$C$125*$AP30 -> 0 | AW30: 0 | AX30: 0
A31: 45926 | B31: 876 | C31: {=IF(B31=0, 0, B31 - INDEX(B$4:B30, MAX(IF(B$4:B30<>0, ROW(B$4:B30)-ROW(B$4)+1))))} -> 120 | D31: 0 | E31: 0 | F31: 32 | G31: =E31+F31 -> 32 | H31: =D31+G31 -> 32 | I31: 44 | J31: 80 | K31: =J31-I31 -> 36 | L31: 0.8125 | M31: 0.033333333 | N31: 5.8 | O31: 282 | P31: =IF(H31>0,C31/H31,0) -> 3.75 | Q31: 0.39 | R31: {=INDEX(FPLBillHistory_BilledPricePerKW_Range, MATCH(1, (A31>=FPLBillHistory_BillFromDate_Range)*(A31<=FPLBillHistory_BillToDate_Range), 0))} -> 0.13702268 | S31: =D31*Q31 -> 0 | T31: =G31*R31 -> 4.3847257 | U31: =SUM(S31:T31) -> 4.3847257 | V31: 2.79 | W31: =C31/MPG_Kia -> 4.8 | X31: =V31*W31 -> 13.392 | Y31: =X31-U31 -> 9.0072743 | Z31: =IFERROR((X31-U31)/X31,0) -> 0.67258619 | AA31: =G31*Q31-G31*R31 -> 8.0952743 | AB31: =H31*Q31 -> 12.48 | AC31: =V31*W31 -> 13.392 | AD31: =H31*R31 -> 4.3847257 | AE31: =X31-AB31 -> 0.912 | AF31: =X31-AD31 -> 9.0072743 | AG31: =AB31-AD31 -> 8.0952743 | AH31: ='Gas Chemistry'!$B$11*$W31 -> 94.08 | AI31: ='Gas Chemistry'!$B$12*$W31 -> 38.4 | AJ31: 0 | AK31: ='Gas Chemistry'!$B$13*$W31 -> 0.096 | AL31: ='Gas Chemistry'!$B$14*$W31 -> 0.048 | AM31: ='Gas Chemistry'!$B$15*$W31 -> 0.0096 | AN31: ='Gas Chemistry'!$B$16*$W31 -> 0.0048 | AO31: ='Gas Chemistry'!$B$17*$W31 -> 0.0192 | AP31: =H31*Constants!$C$14 -> 109.184 | AQ31: ='Gas Chemistry'!$C$122*$AP31 -> 12.774528 | AR31: ='Gas Chemistry'!$C$123*$AP31 -> 15.722496 | AS31: ='Gas Chemistry'!$C$127*$AP31 -> 513.1648 | AT31: ='Gas Chemistry'!$C$124*$AP31 -> 0.009171456 | AU31: ='Gas Chemistry'!$C$126*$AP31 -> 0.0109184 | AV31: ='Gas Chemistry'!$C$125*$AP31 -> 0.00054592 | AW31: 0 | AX31: 0
A32: 45927 | B32: 0 | C32: {=IF(B32=0, 0, B32 - INDEX(B$4:B31, MAX(IF(B$4:B31<>0, ROW(B$4:B31)-ROW(B$4)+1))))} -> 0 | D32: 0 | E32: 0 | F32: 0 | G32: =E32+F32 -> 0 | H32: =D32+G32 -> 0 | I32: 0 | J32: 0 | K32: =J32-I32 -> 0 | N32: 0 | O32: 0 | P32: =IF(H32>0,C32/H32,0) -> 0 | Q32: 0 | R32: {=INDEX(FPLBillHistory_BilledPricePerKW_Range, MATCH(1, (A32>=FPLBillHistory_BillFromDate_Range)*(A32<=FPLBillHistory_BillToDate_Range), 0))} -> 0.13702268 | S32: =D32*Q32 -> 0 | T32: =G32*R32 -> 0 | U32: =SUM(S32:T32) -> 0 | V32: 0 | W32: =C32/MPG_Kia -> 0 | X32: =V32*W32 -> 0 | Y32: =X32-U32 -> 0 | Z32: =IFERROR((X32-U32)/X32,0) -> 0 | AA32: =G32*Q32-G32*R32 -> 0 | AB32: =H32*Q32 -> 0 | AC32: =V32*W32 -> 0 | AD32: =H32*R32 -> 0 | AE32: =X32-AB32 -> 0 | AF32: =X32-AD32 -> 0 | AG32: =AB32-AD32 -> 0 | AH32: ='Gas Chemistry'!$B$11*$W32 -> 0 | AI32: ='Gas Chemistry'!$B$12*$W32 -> 0 | AJ32: 0 | AK32: ='Gas Chemistry'!$B$13*$W32 -> 0 | AL32: ='Gas Chemistry'!$B$14*$W32 -> 0 | AM32: ='Gas Chemistry'!$B$15*$W32 -> 0 | AN32: ='Gas Chemistry'!$B$16*$W32 -> 0 | AO32: ='Gas Chemistry'!$B$17*$W32 -> 0 | AP32: =H32*Constants!$C$14 -> 0 | AQ32: ='Gas Chemistry'!$C$122*$AP32 -> 0 | AR32: ='Gas Chemistry'!$C$123*$AP32 -> 0 | AS32: ='Gas Chemistry'!$C$127*$AP32 -> 0 | AT32: ='Gas Chemistry'!$C$124*$AP32 -> 0 | AU32: ='Gas Chemistry'!$C$126*$AP32 -> 0 | AV32: ='Gas Chemistry'!$C$125*$AP32 -> 0 | AW32: 0 | AX32: 0
A33: 45928 | B33: 883 | C33: {=IF(B33=0, 0, B33 - INDEX(B$4:B32, MAX(IF(B$4:B32<>0, ROW(B$4:B32)-ROW(B$4)+1))))} -> 7 | D33: 0 | E33: 0 | F33: 8 | G33: =E33+F33 -> 8 | H33: =D33+G33 -> 8 | I33: 75 | J33: 80 | K33: =J33-I33 -> 5 | L33: 0.041666667 | M33: 0.074305556 | N33: 0.75 | O33: 282 | P33: =IF(H33>0,C33/H33,0) -> 0.875 | Q33: 0.39 | R33: {=INDEX(FPLBillHistory_BilledPricePerKW_Range, MATCH(1, (A33>=FPLBillHistory_BillFromDate_Range)*(A33<=FPLBillHistory_BillToDate_Range), 0))} -> 0.13702268 | S33: =D33*Q33 -> 0 | T33: =G33*R33 -> 1.0961814 | U33: =SUM(S33:T33) -> 1.0961814 | V33: 2.79 | W33: =C33/MPG_Kia -> 0.28 | X33: =V33*W33 -> 0.7812 | Y33: =X33-U33 -> -0.31498142 | Z33: =IFERROR((X33-U33)/X33,0) -> -0.40320202 | AA33: =G33*Q33-G33*R33 -> 2.0238186 | AB33: =H33*Q33 -> 3.12 | AC33: =V33*W33 -> 0.7812 | AD33: =H33*R33 -> 1.0961814 | AE33: =X33-AB33 -> -2.3388 | AF33: =X33-AD33 -> -0.31498142 | AG33: =AB33-AD33 -> 2.0238186 | AH33: ='Gas Chemistry'!$B$11*$W33 -> 5.488 | AI33: ='Gas Chemistry'!$B$12*$W33 -> 2.24 | AJ33: 0 | AK33: ='Gas Chemistry'!$B$13*$W33 -> 0.0056 | AL33: ='Gas Chemistry'!$B$14*$W33 -> 0.0028 | AM33: ='Gas Chemistry'!$B$15*$W33 -> 0.00056 | AN33: ='Gas Chemistry'!$B$16*$W33 -> 0.00028 | AO33: ='Gas Chemistry'!$B$17*$W33 -> 0.00112 | AP33: =H33*Constants!$C$14 -> 27.296 | AQ33: ='Gas Chemistry'!$C$122*$AP33 -> 3.193632 | AR33: ='Gas Chemistry'!$C$123*$AP33 -> 3.930624 | AS33: ='Gas Chemistry'!$C$127*$AP33 -> 128.2912 | AT33: ='Gas Chemistry'!$C$124*$AP33 -> 0.002292864 | AU33: ='Gas Chemistry'!$C$126*$AP33 -> 0.0027296 | AV33: ='Gas Chemistry'!$C$125*$AP33 -> 0.00013648 | AW33: 0 | AX33: 0
A34: 45929 | B34: 966 | C34: {=IF(B34=0, 0, B34 - INDEX(B$4:B33, MAX(IF(B$4:B33<>0, ROW(B$4:B33)-ROW(B$4)+1))))} -> 83 | D34: 0 | E34: 0 | F34: 23 | G34: =E34+F34 -> 23 | H34: =D34+G34 -> 23 | I34: 50 | J34: 80 | K34: =J34-I34 -> 30 | L34: 0.041666667 | M34: 0.22291667 | N34: 4.3 | O34: 282 | P34: =IF(H34>0,C34/H34,0) -> 3.6086957 | Q34: 0.39 | R34: {=INDEX(FPLBillHistory_BilledPricePerKW_Range, MATCH(1, (A34>=FPLBillHistory_BillFromDate_Range)*(A34<=FPLBillHistory_BillToDate_Range), 0))} -> 0.13702268 | S34: =D34*Q34 -> 0 | T34: =G34*R34 -> 3.1515216 | U34: =SUM(S34:T34) -> 3.1515216 | V34: 2.79 | W34: =C34/MPG_Kia -> 3.32 | X34: =V34*W34 -> 9.2628 | Y34: =X34-U34 -> 6.1112784 | Z34: =IFERROR((X34-U34)/X34,0) -> 0.65976577 | AA34: =G34*Q34-G34*R34 -> 5.8184784 | AB34: =H34*Q34 -> 8.97 | AC34: =V34*W34 -> 9.2628 | AD34: =H34*R34 -> 3.1515216 | AE34: =X34-AB34 -> 0.2928 | AF34: =X34-AD34 -> 6.1112784 | AG34: =AB34-AD34 -> 5.8184784 | AH34: ='Gas Chemistry'!$B$11*$W34 -> 65.072 | AI34: ='Gas Chemistry'!$B$12*$W34 -> 26.56 | AJ34: 0 | AK34: ='Gas Chemistry'!$B$13*$W34 -> 0.0664 | AL34: ='Gas Chemistry'!$B$14*$W34 -> 0.0332 | AM34: ='Gas Chemistry'!$B$15*$W34 -> 0.00664 | AN34: ='Gas Chemistry'!$B$16*$W34 -> 0.00332 | AO34: ='Gas Chemistry'!$B$17*$W34 -> 0.01328 | AP34: =H34*Constants!$C$14 -> 78.476 | AQ34: ='Gas Chemistry'!$C$122*$AP34 -> 9.181692 | AR34: ='Gas Chemistry'!$C$123*$AP34 -> 11.300544 | AS34: ='Gas Chemistry'!$C$127*$AP34 -> 368.8372 | AT34: ='Gas Chemistry'!$C$124*$AP34 -> 0.006591984 | AU34: ='Gas Chemistry'!$C$126*$AP34 -> 0.0078476 | AV34: ='Gas Chemistry'!$C$125*$AP34 -> 0.00039238 | AW34: 0 | AX34: 0
A35: 45930 | B35: 0 | C35: {=IF(B35=0, 0, B35 - INDEX(B$4:B34, MAX(IF(B$4:B34<>0, ROW(B$4:B34)-ROW(B$4)+1))))} -> 0 | D35: 0 | E35: 0 | F35: 0 | G35: =E35+F35 -> 0 | H35: =D35+G35 -> 0 | I35: 0 | J35: 0 | K35: =J35-I35 -> 0 | N35: 0 | O35: 0 | P35: =IF(H35>0,C35/H35,0) -> 0 | Q35: 0 | R35: {=INDEX(FPLBillHistory_BilledPricePerKW_Range, MATCH(1, (A35>=FPLBillHistory_BillFromDate_Range)*(A35<=FPLBillHistory_BillToDate_Range), 0))} -> 0.13702268 | S35: =D35*Q35 -> 0 | T35: =G35*R35 -> 0 | U35: =SUM(S35:T35) -> 0 | V35: 0 | W35: =C35/MPG_Kia -> 0 | X35: =V35*W35 -> 0 | Y35: =X35-U35 -> 0 | Z35: =IFERROR((X35-U35)/X35,0) -> 0 | AA35: =G35*Q35-G35*R35 -> 0 | AB35: =H35*Q35 -> 0 | AC35: =V35*W35 -> 0 | AD35: =H35*R35 -> 0 | AE35: =X35-AB35 -> 0 | AF35: =X35-AD35 -> 0 | AG35: =AB35-AD35 -> 0 | AH35: ='Gas Chemistry'!$B$11*$W35 -> 0 | AI35: ='Gas Chemistry'!$B$12*$W35 -> 0 | AJ35: 0 | AK35: ='Gas Chemistry'!$B$13*$W35 -> 0 | AL35: ='Gas Chemistry'!$B$14*$W35 -> 0 | AM35: ='Gas Chemistry'!$B$15*$W35 -> 0 | AN35: ='Gas Chemistry'!$B$16*$W35 -> 0 | AO35: ='Gas Chemistry'!$B$17*$W35 -> 0 | AP35: =H35*Constants!$C$14 -> 0 | AQ35: ='Gas Chemistry'!$C$122*$AP35 -> 0 | AR35: ='Gas Chemistry'!$C$123*$AP35 -> 0 | AS35: ='Gas Chemistry'!$C$127*$AP35 -> 0 | AT35: ='Gas Chemistry'!$C$124*$AP35 -> 0 | AU35: ='Gas Chemistry'!$C$126*$AP35 -> 0 | AV35: ='Gas Chemistry'!$C$125*$AP35 -> 0 | AW35: 0 | AX35: 0
A36: 45931 | B36: 0 | C36: {=IF(B36=0, 0, B36 - INDEX(B$4:B35, MAX(IF(B$4:B35<>0, ROW(B$4:B35)-ROW(B$4)+1))))} -> 0 | D36: 0 | E36: 0 | F36: 0 | G36: =E36+F36 -> 0 | H36: =D36+G36 -> 0 | I36: 0 | J36: 0 | K36: =J36-I36 -> 0 | N36: 0 | O36: 0 | P36: =IF(H36>0,C36/H36,0) -> 0 | Q36: 0 | R36: {=INDEX(FPLBillHistory_BilledPricePerKW_Range, MATCH(1, (A36>=FPLBillHistory_BillFromDate_Range)*(A36<=FPLBillHistory_BillToDate_Range), 0))} -> 0.13702268 | S36: =D36*Q36 -> 0 | T36: =G36*R36 -> 0 | U36: =SUM(S36:T36) -> 0 | V36: 0 | W36: =C36/MPG_Kia -> 0 | X36: =V36*W36 -> 0 | Y36: =X36-U36 -> 0 | Z36: =IFERROR((X36-U36)/X36,0) -> 0 | AA36: =G36*Q36-G36*R36 -> 0 | AB36: =H36*Q36 -> 0 | AC36: =V36*W36 -> 0 | AD36: =H36*R36 -> 0 | AE36: =X36-AB36 -> 0 | AF36: =X36-AD36 -> 0 | AG36: =AB36-AD36 -> 0 | AH36: ='Gas Chemistry'!$B$11*$W36 -> 0 | AI36: ='Gas Chemistry'!$B$12*$W36 -> 0 | AJ36: 0 | AK36: ='Gas Chemistry'!$B$13*$W36 -> 0 | AL36: ='Gas Chemistry'!$B$14*$W36 -> 0 | AM36: ='Gas Chemistry'!$B$15*$W36 -> 0 | AN36: ='Gas Chemistry'!$B$16*$W36 -> 0 | AO36: ='Gas Chemistry'!$B$17*$W36 -> 0 | AP36: =H36*Constants!$C$14 -> 0 | AQ36: ='Gas Chemistry'!$C$122*$AP36 -> 0 | AR36: ='Gas Chemistry'!$C$123*$AP36 -> 0 | AS36: ='Gas Chemistry'!$C$127*$AP36 -> 0 | AT36: ='Gas Chemistry'!$C$124*$AP36 -> 0 | AU36: ='Gas Chemistry'!$C$126*$AP36 -> 0 | AV36: ='Gas Chemistry'!$C$125*$AP36 -> 0 | AW36: 0 | AX36: 0
A37: 45932 | B37: 0 | C37: {=IF(B37=0, 0, B37 - INDEX(B$4:B36, MAX(IF(B$4:B36<>0, ROW(B$4:B36)-ROW(B$4)+1))))} -> 0 | D37: 0 | E37: 0 | F37: 0 | G37: =E37+F37 -> 0 | H37: =D37+G37 -> 0 | I37: 0 | J37: 0 | K37: =J37-I37 -> 0 | N37: 0 | O37: 0 | P37: =IF(H37>0,C37/H37,0) -> 0 | Q37: 0 | R37: {=INDEX(FPLBillHistory_BilledPricePerKW_Range, MATCH(1, (A37>=FPLBillHistory_BillFromDate_Range)*(A37<=FPLBillHistory_BillToDate_Range), 0))} -> 0.13702268 | S37: =D37*Q37 -> 0 | T37: =G37*R37 -> 0 | U37: =SUM(S37:T37) -> 0 | V37: 0 | W37: =C37/MPG_Kia -> 0 | X37: =V37*W37 -> 0 | Y37: =X37-U37 -> 0 | Z37: =IFERROR((X37-U37)/X37,0) -> 0 | AA37: =G37*Q37-G37*R37 -> 0 | AB37: =H37*Q37 -> 0 | AC37: =V37*W37 -> 0 | AD37: =H37*R37 -> 0 | AE37: =X37-AB37 -> 0 | AF37: =X37-AD37 -> 0 | AG37: =AB37-AD37 -> 0 | AH37: ='Gas Chemistry'!$B$11*$W37 -> 0 | AI37: ='Gas Chemistry'!$B$12*$W37 -> 0 | AJ37: 0 | AK37: ='Gas Chemistry'!$B$13*$W37 -> 0 | AL37: ='Gas Chemistry'!$B$14*$W37 -> 0 | AM37: ='Gas Chemistry'!$B$15*$W37 -> 0 | AN37: ='Gas Chemistry'!$B$16*$W37 -> 0 | AO37: ='Gas Chemistry'!$B$17*$W37 -> 0 | AP37: =H37*Constants!$C$14 -> 0 | AQ37: ='Gas Chemistry'!$C$122*$AP37 -> 0 | AR37: ='Gas Chemistry'!$C$123*$AP37 -> 0 | AS37: ='Gas Chemistry'!$C$127*$AP37 -> 0 | AT37: ='Gas Chemistry'!$C$124*$AP37 -> 0 | AU37: ='Gas Chemistry'!$C$126*$AP37 -> 0 | AV37: ='Gas Chemistry'!$C$125*$AP37 -> 0 | AW37: 0 | AX37: 0
A38: 45933 | B38: 979 | C38: {=IF(B38=0, 0, B38 - INDEX(B$4:B37, MAX(IF(B$4:B37<>0, ROW(B$4:B37)-ROW(B$4)+1))))} -> 13 | D38: 0 | E38: 0 | F38: 6 | G38: =E38+F38 -> 6 | H38: =D38+G38 -> 6 | I38: 72 | J38: 80 | K38: =J38-I38 -> 8 | L38: 0.041666667 | M38: 0.093055556 | N38: 1.25 | O38: 280 | P38: =IF(H38>0,C38/H38,0) -> 2.1666667 | Q38: 0.39 | R38: {=INDEX(FPLBillHistory_BilledPricePerKW_Range, MATCH(1, (A38>=FPLBillHistory_BillFromDate_Range)*(A38<=FPLBillHistory_BillToDate_Range), 0))} -> 0.13702268 | S38: =D38*Q38 -> 0 | T38: =G38*R38 -> 0.82213606 | U38: =SUM(S38:T38) -> 0.82213606 | V38: 2.79 | W38: =C38/MPG_Kia -> 0.52 | X38: =V38*W38 -> 1.4508 | Y38: =X38-U38 -> 0.62866394 | Z38: =IFERROR((X38-U38)/X38,0) -> 0.43332226 | AA38: =G38*Q38-G38*R38 -> 1.5178639 | AB38: =H38*Q38 -> 2.34 | AC38: =V38*W38 -> 1.4508 | AD38: =H38*R38 -> 0.82213606 | AE38: =X38-AB38 -> -0.8892 | AF38: =X38-AD38 -> 0.62866394 | AG38: =AB38-AD38 -> 1.5178639 | AH38: ='Gas Chemistry'!$B$11*$W38 -> 10.192 | AI38: ='Gas Chemistry'!$B$12*$W38 -> 4.16 | AJ38: 0 | AK38: ='Gas Chemistry'!$B$13*$W38 -> 0.0104 | AL38: ='Gas Chemistry'!$B$14*$W38 -> 0.0052 | AM38: ='Gas Chemistry'!$B$15*$W38 -> 0.00104 | AN38: ='Gas Chemistry'!$B$16*$W38 -> 0.00052 | AO38: ='Gas Chemistry'!$B$17*$W38 -> 0.00208 | AP38: =H38*Constants!$C$14 -> 20.472 | AQ38: ='Gas Chemistry'!$C$122*$AP38 -> 2.395224 | AR38: ='Gas Chemistry'!$C$123*$AP38 -> 2.947968 | AS38: ='Gas Chemistry'!$C$127*$AP38 -> 96.2184 | AT38: ='Gas Chemistry'!$C$124*$AP38 -> 0.001719648 | AU38: ='Gas Chemistry'!$C$126*$AP38 -> 0.0020472 | AV38: ='Gas Chemistry'!$C$125*$AP38 -> 0.00010236 | AW38: 0 | AX38: 0
A39: 45934 | B39: 1014 | C39: {=IF(B39=0, 0, B39 - INDEX(B$4:B38, MAX(IF(B$4:B38<>0, ROW(B$4:B38)-ROW(B$4)+1))))} -> 35 | D39: 0 | E39: 0 | F39: 27 | G39: =E39+F39 -> 27 | H39: =D39+G39 -> 27 | I39: 64 | J39: 100 | K39: =J39-I39 -> 36 | L39: 0.041666667 | M39: 0.26944444 | N39: 5.5 | O39: 353 | P39: =IF(H39>0,C39/H39,0) -> 1.2962963 | Q39: 0.4 | R39: {=INDEX(FPLBillHistory_BilledPricePerKW_Range, MATCH(1, (A39>=FPLBillHistory_BillFromDate_Range)*(A39<=FPLBillHistory_BillToDate_Range), 0))} -> 0.13702268 | S39: =D39*Q39 -> 0 | T39: =G39*R39 -> 3.6996123 | U39: =SUM(S39:T39) -> 3.6996123 | V39: 2.79 | W39: =C39/MPG_Kia -> 1.4 | X39: =V39*W39 -> 3.906 | Y39: =X39-U39 -> 0.20638771 | Z39: =IFERROR((X39-U39)/X39,0) -> 0.052838636 | AA39: =G39*Q39-G39*R39 -> 7.1003877 | AB39: =H39*Q39 -> 10.8 | AC39: =V39*W39 -> 3.906 | AD39: =H39*R39 -> 3.6996123 | AE39: =X39-AB39 -> -6.894 | AF39: =X39-AD39 -> 0.20638771 | AG39: =AB39-AD39 -> 7.1003877 | AH39: ='Gas Chemistry'!$B$11*$W39 -> 27.44 | AI39: ='Gas Chemistry'!$B$12*$W39 -> 11.2 | AJ39: 0 | AK39: ='Gas Chemistry'!$B$13*$W39 -> 0.028 | AL39: ='Gas Chemistry'!$B$14*$W39 -> 0.014 | AM39: ='Gas Chemistry'!$B$15*$W39 -> 0.0028 | AN39: ='Gas Chemistry'!$B$16*$W39 -> 0.0014 | AO39: ='Gas Chemistry'!$B$17*$W39 -> 0.0056 | AP39: =H39*Constants!$C$14 -> 92.124 | AQ39: ='Gas Chemistry'!$C$122*$AP39 -> 10.778508 | AR39: ='Gas Chemistry'!$C$123*$AP39 -> 13.265856 | AS39: ='Gas Chemistry'!$C$127*$AP39 -> 432.9828 | AT39: ='Gas Chemistry'!$C$124*$AP39 -> 0.007738416 | AU39: ='Gas Chemistry'!$C$126*$AP39 -> 0.0092124 | AV39: ='Gas Chemistry'!$C$125*$AP39 -> 0.00046062 | AW39: 0 | AX39: 0
A40: 45935 | B40: 1264 | C40: {=IF(B40=0, 0, B40 - INDEX(B$4:B39, MAX(IF(B$4:B39<>0, ROW(B$4:B39)-ROW(B$4)+1))))} -> 250 | D40: 18 | E40: 0 | F40: 29 | G40: =E40+F40 -> 29 | H40: =D40+G40 -> 47 | I40: 43 | J40: 80 | K40: =J40-I40 -> 37 | L40: 0.041666667 | M40: 0.26736111 | N40: 5.5 | O40: 280 | P40: =IF(H40>0,C40/H40,0) -> 5.3191489 | Q40: 0.4 | R40: {=INDEX(FPLBillHistory_BilledPricePerKW_Range, MATCH(1, (A40>=FPLBillHistory_BillFromDate_Range)*(A40<=FPLBillHistory_BillToDate_Range), 0))} -> 0.13702268 | S40: =D40*Q40 -> 7.2 | T40: =G40*R40 -> 3.9736576 | U40: =SUM(S40:T40) -> 11.173658 | V40: 2.79 | W40: =C40/MPG_Kia -> 10 | X40: =V40*W40 -> 27.9 | Y40: =X40-U40 -> 16.726342 | Z40: =IFERROR((X40-U40)/X40,0) -> 0.59951048 | AA40: =G40*Q40-G40*R40 -> 7.6263424 | AB40: =H40*Q40 -> 18.8 | AC40: =V40*W40 -> 27.9 | AD40: =H40*R40 -> 6.4400658 | AE40: =X40-AB40 -> 9.1 | AF40: =X40-AD40 -> 21.459934 | AG40: =AB40-AD40 -> 12.359934 | AH40: ='Gas Chemistry'!$B$11*$W40 -> 196 | AI40: ='Gas Chemistry'!$B$12*$W40 -> 80 | AJ40: 0 | AK40: ='Gas Chemistry'!$B$13*$W40 -> 0.2 | AL40: ='Gas Chemistry'!$B$14*$W40 -> 0.1 | AM40: ='Gas Chemistry'!$B$15*$W40 -> 0.02 | AN40: ='Gas Chemistry'!$B$16*$W40 -> 0.01 | AO40: ='Gas Chemistry'!$B$17*$W40 -> 0.04 | AP40: =H40*Constants!$C$14 -> 160.364 | AQ40: ='Gas Chemistry'!$C$122*$AP40 -> 18.762588 | AR40: ='Gas Chemistry'!$C$123*$AP40 -> 23.092416 | AS40: ='Gas Chemistry'!$C$127*$AP40 -> 753.7108 | AT40: ='Gas Chemistry'!$C$124*$AP40 -> 0.013470576 | AU40: ='Gas Chemistry'!$C$126*$AP40 -> 0.0160364 | AV40: ='Gas Chemistry'!$C$125*$AP40 -> 0.00080182 | AW40: 0 | AX40: 0
